Workbook

Sheet WarriorMastery
A1: string[64] | B1: dword | C1: dword | D1: dword | E1: dword | F1: dword | G1: dword | H1: dword | I1: dword | J1: dword | K1: dword | L1: dword | M1: dword | N1: dword | O1: dword | P1: dword | Q1: dword | R1: dword | S1: dword | T1: dword | U1: dword | V1: dword | W1: dword | X1: dword | Y1: dword | Z1: dword | AA1: dword | AB1: dword | AC1: dword | AD1: dword | AE1: dword | AF1: dword | AG1: dword | AH1: dword | AI1: dword | AJ1: dword | AK1: dword | AL1: dword | AM1: dword | AN1: dword | AO1: dword | AP1: dword | AQ1: END
A2: Name | B2: Lv | C2: MelePT | D2: RangePT | E2: SpecialPT | F2: DefPT | G2: ShieldPT | H2: CraftPt1 | I2: CraftPt2 | J2: CraftPt3 | K2: MeleYch | L2: MeleExp | M2: MeleElitr | N2: MeleMagistr | O2: RangeYch | P2: RangeExp | Q2: RangeElite | R2: RangeMagistr | S2: Dark1 | T2: Dark2 | U2: Dark3 | V2: Dark4 | W2: Holy1 | X2: Holy2 | Y2: Holy3 | Z2: Holy4 | AA2: Fire1 | AB2: Fire2 | AC2: Fire3 | AD2: Fire4 | AE2: Water1 | AF2: Water2 | AG2: Water3 | AH2: Water4 | AI2: Soil1 | AJ2: Soil2 | AK2: Soil3 | AL2: Soil4 | AM2: Wind1 | AN2: Wind2 | AO2: Wind3 | AP2: Wind4
A3: 0 | B3: 1 | C3: 3 | D3: 2 | E3: 2 | F3: 2 | G3: 2 | H3: 1 | I3: 1 | J3: 1 | K3: 5 | L3: 1 | M3: 1 | N3: 1 | O3: 2 | P3: 1 | Q3: 1 | R3: 1 | S3: 2 | T3: 1 | U3: 1 | V3: 1 | W3: 2 | X3: 1 | Y3: 1 | Z3: 1 | AA3: 2 | AB3: 1 | AC3: 1 | AD3: 1 | AE3: 2 | AF3: 1 | AG3: 1 | AH3: 1 | AI3: 2 | AJ3: 1 | AK3: 1 | AL3: 1 | AM3: 2 | AN3: 1 | AO3: 1 | AP3: 1
A4: 0 | B4: 2 | C4: 4 | D4: 3 | E4: 3 | F4: 3 | G4: 3 | H4: 1 | I4: 1 | J4: 1 | K4: 5 | L4: 1 | M4: 1 | N4: 1 | O4: 3 | P4: 1 | Q4: 1 | R4: 1 | S4: 3 | T4: 1 | U4: 1 | V4: 1 | W4: 3 | X4: 1 | Y4: 1 | Z4: 1 | AA4: 3 | AB4: 1 | AC4: 1 | AD4: 1 | AE4: 3 | AF4: 1 | AG4: 1 | AH4: 1 | AI4: 3 | AJ4: 1 | AK4: 1 | AL4: 1 | AM4: 3 | AN4: 1 | AO4: 1 | AP4: 1
A5: 0 | B5: 3 | C5: 5 | D5: 4 | E5: 4 | F5: 4 | G5: 4 | H5: 1 | I5: 1 | J5: 1 | K5: 5 | L5: 1 | M5: 1 | N5: 1 | O5: 3 | P5: 1 | Q5: 1 | R5: 1 | S5: 3 | T5: 1 | U5: 1 | V5: 1 | W5: 3 | X5: 1 | Y5: 1 | Z5: 1 | AA5: 3 | AB5: 1 | AC5: 1 | AD5: 1 | AE5: 3 | AF5: 1 | AG5: 1 | AH5: 1 | AI5: 3 | AJ5: 1 | AK5: 1 | AL5: 1 | AM5: 3 | AN5: 1 | AO5: 1 | AP5: 1
A6: 0 | B6: 4 | C6: 6 | D6: 4 | E6: 5 | F6: 5 | G6: 5 | H6: 1 | I6: 1 | J6: 1 | K6: 6 | L6: 1 | M6: 1 | N6: 1 | O6: 4 | P6: 1 | Q6: 1 | R6: 1 | S6: 4 | T6: 1 | U6: 1 | V6: 1 | W6: 4 | X6: 1 | Y6: 1 | Z6: 1 | AA6: 4 | AB6: 1 | AC6: 1 | AD6: 1 | AE6: 4 | AF6: 1 | AG6: 1 | AH6: 1 | AI6: 4 | AJ6: 1 | AK6: 1 | AL6: 1 | AM6: 4 | AN6: 1 | AO6: 1 | AP6: 1
A7: 0 | B7: 5 | C7: 7 | D7: 5 | E7: 6 | F7: 6 | G7: 6 | H7: 1 | I7: 1 | J7: 1 | K7: 7 | L7: 1 | M7: 1 | N7: 1 | O7: 5 | P7: 1 | Q7: 1 | R7: 1 | S7: 5 | T7: 1 | U7: 1 | V7: 1 | W7: 5 | X7: 1 | Y7: 1 | Z7: 1 | AA7: 5 | AB7: 1 | AC7: 1 | AD7: 1 | AE7: 5 | AF7: 1 | AG7: 1 | AH7: 1 | AI7: 5 | AJ7: 1 | AK7: 1 | AL7: 1 | AM7: 5 | AN7: 1 | AO7: 1 | AP7: 1
A8: 0 | B8: 6 | C8: 8 | D8: 6 | E8: 7 | F8: 7 | G8: 7 | H8: 1 | I8: 1 | J8: 1 | K8: 8 | L8: 1 | M8: 1 | N8: 1 | O8: 5 | P8: 1 | Q8: 1 | R8: 1 | S8: 5 | T8: 1 | U8: 1 | V8: 1 | W8: 5 | X8: 1 | Y8: 1 | Z8: 1 | AA8: 5 | AB8: 1 | AC8: 1 | AD8: 1 | AE8: 5 | AF8: 1 | AG8: 1 | AH8: 1 | AI8: 5 | AJ8: 1 | AK8: 1 | AL8: 1 | AM8: 5 | AN8: 1 | AO8: 1 | AP8: 1
A9: 0 | B9: 7 | C9: 9 | D9: 7 | E9: 8 | F9: 8 | G9: 8 | H9: 1 | I9: 1 | J9: 1 | K9: 8 | L9: 1 | M9: 1 | N9: 1 | O9: 5 | P9: 1 | Q9: 1 | R9: 1 | S9: 5 | T9: 1 | U9: 1 | V9: 1 | W9: 5 | X9: 1 | Y9: 1 | Z9: 1 | AA9: 5 | AB9: 1 | AC9: 1 | AD9: 1 | AE9: 5 | AF9: 1 | AG9: 1 | AH9: 1 | AI9: 5 | AJ9: 1 | AK9: 1 | AL9: 1 | AM9: 5 | AN9: 1 | AO9: 1 | AP9: 1
A10: 0 | B10: 8 | C10: 10 | D10: 7 | E10: 9 | F10: 9 | G10: 9 | H10: 1 | I10: 1 | J10: 1 | K10: 9 | L10: 1 | M10: 1 | N10: 1 | O10: 6 | P10: 1 | Q10: 1 | R10: 1 | S10: 6 | T10: 1 | U10: 1 | V10: 1 | W10: 6 | X10: 1 | Y10: 1 | Z10: 1 | AA10: 6 | AB10: 1 | AC10: 1 | AD10: 1 | AE10: 6 | AF10: 1 | AG10: 1 | AH10: 1 | AI10: 6 | AJ10: 1 | AK10: 1 | AL10: 1 | AM10: 6 | AN10: 1 | AO10: 1 | AP10: 1
A11: 0 | B11: 9 | C11: 12 | D11: 8 | E11: 9 | F11: 9 | G11: 9 | H11: 1 | I11: 1 | J11: 1 | K11: 10 | L11: 1 | M11: 1 | N11: 1 | O11: 7 | P11: 1 | Q11: 1 | R11: 1 | S11: 7 | T11: 1 | U11: 1 | V11: 1 | W11: 7 | X11: 1 | Y11: 1 | Z11: 1 | AA11: 7 | AB11: 1 | AC11: 1 | AD11: 1 | AE11: 7 | AF11: 1 | AG11: 1 | AH11: 1 | AI11: 7 | AJ11: 1 | AK11: 1 | AL11: 1 | AM11: 7 | AN11: 1 | AO11: 1 | AP11: 1
A12: 0 | B12: 10 | C12: 13 | D12: 9 | E12: 10 | F12: 10 | G12: 10 | H12: 1 | I12: 1 | J12: 1 | K12: 11 | L12: 1 | M12: 1 | N12: 1 | O12: 7 | P12: 1 | Q12: 1 | R12: 1 | S12: 7 | T12: 1 | U12: 1 | V12: 1 | W12: 7 | X12: 1 | Y12: 1 | Z12: 1 | AA12: 7 | AB12: 1 | AC12: 1 | AD12: 1 | AE12: 7 | AF12: 1 | AG12: 1 | AH12: 1 | AI12: 7 | AJ12: 1 | AK12: 1 | AL12: 1 | AM12: 7 | AN12: 1 | AO12: 1 | AP12: 1
A13: 0 | B13: 11 | C13: 14 | D13: 10 | E13: 11 | F13: 11 | G13: 11 | H13: 1 | I13: 1 | J13: 1 | K13: 11 | L13: 1 | M13: 1 | N13: 1 | O13: 7 | P13: 1 | Q13: 1 | R13: 1 | S13: 7 | T13: 1 | U13: 1 | V13: 1 | W13: 7 | X13: 1 | Y13: 1 | Z13: 1 | AA13: 7 | AB13: 1 | AC13: 1 | AD13: 1 | AE13: 7 | AF13: 1 | AG13: 1 | AH13: 1 | AI13: 7 | AJ13: 1 | AK13: 1 | AL13: 1 | AM13: 7 | AN13: 1 | AO13: 1 | AP13: 1
A14: 0 | B14: 12 | C14: 15 | D14: 10 | E14: 12 | F14: 12 | G14: 12 | H14: 1 | I14: 1 | J14: 1 | K14: 12 | L14: 1 | M14: 1 | N14: 1 | O14: 8 | P14: 1 | Q14: 1 | R14: 1 | S14: 8 | T14: 1 | U14: 1 | V14: 1 | W14: 8 | X14: 1 | Y14: 1 | Z14: 1 | AA14: 8 | AB14: 1 | AC14: 1 | AD14: 1 | AE14: 8 | AF14: 1 | AG14: 1 | AH14: 1 | AI14: 8 | AJ14: 1 | AK14: 1 | AL14: 1 | AM14: 8 | AN14: 1 | AO14: 1 | AP14: 1
... A83: 0 | B83: 81 | C83: 99 | D83: 60 | E83: 99 | F83: 99 | G83: 99 | H83: 1 | I83: 1 | J83: 1 | K83: 99 | L83: 99 | M83: 99 | N83: 99 | O83: 66 | P83: 1 | Q83: 1 | R83: 1 | S83: 66 | T83: 1 | U83: 1 | V83: 1 | W83: 66 | X83: 1 | Y83: 1 | Z83: 1 | AA83: 66 | AB83: 1 | AC83: 1 | AD83: 1 | AE83: 66 | AF83: 1 | AG83: 1 | AH83: 1 | AI83: 66 | AJ83: 1 | AK83: 1 | AL83: 1 | AM83: 66 | AN83: 1 | AO83: 1 | AP83: 1

Sheet RangerMastery
A1: string[64] | B1: dword | C1: dword | D1: dword | E1: dword | F1: dword | G1: dword | H1: dword | I1: dword | J1: dword | K1: dword | L1: dword | M1: dword | N1: dword | O1: dword | P1: dword | Q1: dword | R1: dword | S1: dword | T1: dword | U1: dword | V1: dword | W1: dword | X1: dword | Y1: dword | Z1: dword | AA1: dword | AB1: dword | AC1: dword | AD1: dword | AE1: dword | AF1: dword | AG1: dword | AH1: dword | AI1: dword | AJ1: dword | AK1: dword | AL1: dword | AM1: dword | AN1: dword | AO1: dword | AP1: dword | AQ1: END
A2: Name | B2: Lv | C2: MelePT | D2: RangePT | E2: SpecialPT | F2: DefPT | G2: ShieldPT | H2: CraftPt1 | I2: CraftPt2 | J2: CraftPt3 | K2: MeleYch | L2: MeleExp | M2: MeleElitr | N2: MeleMagistr | O2: RangeYch | P2: RangeExp | Q2: RangeElite | R2: RangeMagistr | S2: Dark1 | T2: Dark2 | U2: Dark3 | V2: Dark4 | W2: Holy1 | X2: Holy2 | Y2: Holy3 | Z2: Holy4 | AA2: Fire1 | AB2: Fire2 | AC2: Fire3 | AD2: Fire4 | AE2: Water1 | AF2: Water2 | AG2: Water3 | AH2: Water4 | AI2: Soil1 | AJ2: Soil2 | AK2: Soil3 | AL2: Soil4 | AM2: Wind1 | AN2: Wind2 | AO2: Wind3 | AP2: Wind4
A3: 0 | B3: 1 | C3: 2 | D3: 3 | E3: 2 | F3: 2 | G3: 2 | H3: 1 | I3: 1 | J3: 1 | K3: 2 | L3: 1 | M3: 1 | N3: 1 | O3: 5 | P3: 1 | Q3: 1 | R3: 1 | S3: 2 | T3: 1 | U3: 1 | V3: 1 | W3: 2 | X3: 1 | Y3: 1 | Z3: 1 | AA3: 2 | AB3: 1 | AC3: 1 | AD3: 1 | AE3: 2 | AF3: 1 | AG3: 1 | AH3: 1 | AI3: 2 | AJ3: 1 | AK3: 1 | AL3: 1 | AM3: 2 | AN3: 1 | AO3: 1 | AP3: 1
A4: 0 | B4: 2 | C4: 3 | D4: 4 | E4: 3 | F4: 3 | G4: 3 | H4: 1 | I4: 1 | J4: 1 | K4: 3 | L4: 1 | M4: 1 | N4: 1 | O4: 5 | P4: 1 | Q4: 1 | R4: 1 | S4: 3 | T4: 1 | U4: 1 | V4: 1 | W4: 3 | X4: 1 | Y4: 1 | Z4: 1 | AA4: 3 | AB4: 1 | AC4: 1 | AD4: 1 | AE4: 3 | AF4: 1 | AG4: 1 | AH4: 1 | AI4: 3 | AJ4: 1 | AK4: 1 | AL4: 1 | AM4: 3 | AN4: 1 | AO4: 1 | AP4: 1
A5: 0 | B5: 3 | C5: 4 | D5: 5 | E5: 4 | F5: 4 | G5: 3 | H5: 1 | I5: 1 | J5: 1 | K5: 3 | L5: 1 | M5: 1 | N5: 1 | O5: 5 | P5: 1 | Q5: 1 | R5: 1 | S5: 3 | T5: 1 | U5: 1 | V5: 1 | W5: 3 | X5: 1 | Y5: 1 | Z5: 1 | AA5: 3 | AB5: 1 | AC5: 1 | AD5: 1 | AE5: 3 | AF5: 1 | AG5: 1 | AH5: 1 | AI5: 3 | AJ5: 1 | AK5: 1 | AL5: 1 | AM5: 3 | AN5: 1 | AO5: 1 | AP5: 1
A6: 0 | B6: 4 | C6: 4 | D6: 6 | E6: 5 | F6: 5 | G6: 4 | H6: 1 | I6: 1 | J6: 1 | K6: 4 | L6: 1 | M6: 1 | N6: 1 | O6: 6 | P6: 1 | Q6: 1 | R6: 1 | S6: 4 | T6: 1 | U6: 1 | V6: 1 | W6: 4 | X6: 1 | Y6: 1 | Z6: 1 | AA6: 4 | AB6: 1 | AC6: 1 | AD6: 1 | AE6: 4 | AF6: 1 | AG6: 1 | AH6: 1 | AI6: 4 | AJ6: 1 | AK6: 1 | AL6: 1 | AM6: 4 | AN6: 1 | AO6: 1 | AP6: 1
A7: 0 | B7: 5 | C7: 5 | D7: 7 | E7: 6 | F7: 6 | G7: 4 | H7: 1 | I7: 1 | J7: 1 | K7: 5 | L7: 1 | M7: 1 | N7: 1 | O7: 7 | P7: 1 | Q7: 1 | R7: 1 | S7: 5 | T7: 1 | U7: 1 | V7: 1 | W7: 5 | X7: 1 | Y7: 1 | Z7: 1 | AA7: 5 | AB7: 1 | AC7: 1 | AD7: 1 | AE7: 5 | AF7: 1 | AG7: 1 | AH7: 1 | AI7: 5 | AJ7: 1 | AK7: 1 | AL7: 1 | AM7: 5 | AN7: 1 | AO7: 1 | AP7: 1
A8: 0 | B8: 6 | C8: 6 | D8: 8 | E8: 7 | F8: 7 | G8: 5 | H8: 1 | I8: 1 | J8: 1 | K8: 5 | L8: 1 | M8: 1 | N8: 1 | O8: 8 | P8: 1 | Q8: 1 | R8: 1 | S8: 5 | T8: 1 | U8: 1 | V8: 1 | W8: 5 | X8: 1 | Y8: 1 | Z8: 1 | AA8: 5 | AB8: 1 | AC8: 1 | AD8: 1 | AE8: 5 | AF8: 1 | AG8: 1 | AH8: 1 | AI8: 5 | AJ8: 1 | AK8: 1 | AL8: 1 | AM8: 5 | AN8: 1 | AO8: 1 | AP8: 1
A9: 0 | B9: 7 | C9: 7 | D9: 9 | E9: 8 | F9: 8 | G9: 6 | H9: 1 | I9: 1 | J9: 1 | K9: 5 | L9: 1 | M9: 1 | N9: 1 | O9: 8 | P9: 1 | Q9: 1 | R9: 1 | S9: 5 | T9: 1 | U9: 1 | V9: 1 | W9: 5 | X9: 1 | Y9: 1 | Z9: 1 | AA9: 5 | AB9: 1 | AC9: 1 | AD9: 1 | AE9: 5 | AF9: 1 | AG9: 1 | AH9: 1 | AI9: 5 | AJ9: 1 | AK9: 1 | AL9: 1 | AM9: 5 | AN9: 1 | AO9: 1 | AP9: 1
A10: 0 | B10: 8 | C10: 7 | D10: 10 | E10: 9 | F10: 9 | G10: 6 | H10: 1 | I10: 1 | J10: 1 | K10: 6 | L10: 1 | M10: 1 | N10: 1 | O10: 9 | P10: 1 | Q10: 1 | R10: 1 | S10: 6 | T10: 1 | U10: 1 | V10: 1 | W10: 6 | X10: 1 | Y10: 1 | Z10: 1 | AA10: 6 | AB10: 1 | AC10: 1 | AD10: 1 | AE10: 6 | AF10: 1 | AG10: 1 | AH10: 1 | AI10: 6 | AJ10: 1 | AK10: 1 | AL10: 1 | AM10: 6 | AN10: 1 | AO10: 1 | AP10: 1
A11: 0 | B11: 9 | C11: 8 | D11: 12 | E11: 9 | F11: 9 | G11: 7 | H11: 1 | I11: 1 | J11: 1 | K11: 7 | L11: 1 | M11: 1 | N11: 1 | O11: 10 | P11: 1 | Q11: 1 | R11: 1 | S11: 7 | T11: 1 | U11: 1 | V11: 1 | W11: 7 | X11: 1 | Y11: 1 | Z11: 1 | AA11: 7 | AB11: 1 | AC11: 1 | AD11: 1 | AE11: 7 | AF11: 1 | AG11: 1 | AH11: 1 | AI11: 7 | AJ11: 1 | AK11: 1 | AL11: 1 | AM11: 7 | AN11: 1 | AO11: 1 | AP11: 1
A12: 0 | B12: 10 | C12: 9 | D12: 13 | E12: 10 | F12: 10 | G12: 7 | H12: 1 | I12: 1 | J12: 1 | K12: 7 | L12: 1 | M12: 1 | N12: 1 | O12: 11 | P12: 1 | Q12: 1 | R12: 1 | S12: 7 | T12: 1 | U12: 1 | V12: 1 | W12: 7 | X12: 1 | Y12: 1 | Z12: 1 | AA12: 7 | AB12: 1 | AC12: 1 | AD12: 1 | AE12: 7 | AF12: 1 | AG12: 1 | AH12: 1 | AI12: 7 | AJ12: 1 | AK12: 1 | AL12: 1 | AM12: 7 | AN12: 1 | AO12: 1 | AP12: 1
A13: 0 | B13: 11 | C13: 10 | D13: 14 | E13: 11 | F13: 11 | G13: 8 | H13: 1 | I13: 1 | J13: 1 | K13: 7 | L13: 1 | M13: 1 | N13: 1 | O13: 11 | P13: 1 | Q13: 1 | R13: 1 | S13: 7 | T13: 1 | U13: 1 | V13: 1 | W13: 7 | X13: 1 | Y13: 1 | Z13: 1 | AA13: 7 | AB13: 1 | AC13: 1 | AD13: 1 | AE13: 7 | AF13: 1 | AG13: 1 | AH13: 1 | AI13: 7 | AJ13: 1 | AK13: 1 | AL13: 1 | AM13: 7 | AN13: 1 | AO13: 1 | AP13: 1
A14: 0 | B14: 12 | C14: 10 | D14: 15 | E14: 12 | F14: 12 | G14: 9 | H14: 1 | I14: 1 | J14: 1 | K14: 8 | L14: 1 | M14: 1 | N14: 1 | O14: 12 | P14: 1 | Q14: 1 | R14: 1 | S14: 8 | T14: 1 | U14: 1 | V14: 1 | W14: 8 | X14: 1 | Y14: 1 | Z14: 1 | AA14: 8 | AB14: 1 | AC14: 1 | AD14: 1 | AE14: 8 | AF14: 1 | AG14: 1 | AH14: 1 | AI14: 8 | AJ14: 1 | AK14: 1 | AL14: 1 | AM14: 8 | AN14: 1 | AO14: 1 | AP14: 1
... A83: 0 | B83: 81 | C83: 60 | D83: 99 | E83: 99 | F83: 99 | G83: 60 | H83: 1 | I83: 1 | J83: 1 | K83: 66 | L83: 1 | M83: 1 | N83: 1 | O83: 99 | P83: 99 | Q83: 99 | R83: 5 | S83: 66 | T83: 1 | U83: 1 | V83: 1 | W83: 66 | X83: 1 | Y83: 1 | Z83: 1 | AA83: 66 | AB83: 1 | AC83: 1 | AD83: 1 | AE83: 66 | AF83: 1 | AG83: 1 | AH83: 1 | AI83: 66 | AJ83: 1 | AK83: 1 | AL83: 1 | AM83: 66 | AN83: 1 | AO83: 1 | AP83: 1

Sheet SpiriutalistMastery
A1: string[64] | B1: dword | C1: dword | D1: dword | E1: dword | F1: dword | G1: dword | H1: dword | I1: dword | J1: dword | K1: dword | L1: dword | M1: dword | N1: dword | O1: dword | P1: dword | Q1: dword | R1: dword | S1: dword | T1: dword | U1: dword | V1: dword | W1: dword | X1: dword | Y1: dword | Z1: dword | AA1: dword | AB1: dword | AC1: dword | AD1: dword | AE1: dword | AF1: dword | AG1: dword | AH1: dword | AI1: dword | AJ1: dword | AK1: dword | AL1: dword | AM1: dword | AN1: dword | AO1: dword | AP1: dword | AQ1: END
A2: Name | B2: Lv | C2: MelePT | D2: RangePT | E2: SpecialPT | F2: DefPT | G2: ShieldPT | H2: CraftPt1 | I2: CraftPt2 | J2: CraftPt3 | K2: MeleYch | L2: MeleExp | M2: MeleElitr | N2: MeleMagistr | O2: RangeYch | P2: RangeExp | Q2: RangeElite | R2: RangeMagistr | S2: Dark1 | T2: Dark2 | U2: Dark3 | V2: Dark4 | W2: Holy1 | X2: Holy2 | Y2: Holy3 | Z2: Holy4 | AA2: Fire1 | AB2: Fire2 | AC2: Fire3 | AD2: Fire4 | AE2: Water1 | AF2: Water2 | AG2: Water3 | AH2: Water4 | AI2: Soil1 | AJ2: Soil2 | AK2: Soil3 | AL2: Soil4 | AM2: Wind1 | AN2: Wind2 | AO2: Wind3 | AP2: Wind4
A3: 0 | B3: 1 | C3: 2 | D3: 2 | E3: 2 | F3: 2 | G3: 2 | H3: 1 | I3: 1 | J3: 1 | K3: 2 | L3: 1 | M3: 1 | N3: 1 | O3: 2 | P3: 1 | Q3: 1 | R3: 1 | S3: 5 | T3: 1 | U3: 1 | V3: 1 | W3: 5 | X3: 1 | Y3: 1 | Z3: 1 | AA3: 5 | AB3: 1 | AC3: 1 | AD3: 1 | AE3: 5 | AF3: 1 | AG3: 1 | AH3: 1 | AI3: 5 | AJ3: 1 | AK3: 1 | AL3: 1 | AM3: 5 | AN3: 1 | AO3: 1 | AP3: 1
A4: 0 | B4: 2 | C4: 3 | D4: 3 | E4: 3 | F4: 3 | G4: 3 | H4: 1 | I4: 1 | J4: 1 | K4: 4 | L4: 1 | M4: 1 | N4: 1 | O4: 4 | P4: 1 | Q4: 1 | R4: 1 | S4: 5 | T4: 1 | U4: 1 | V4: 1 | W4: 5 | X4: 1 | Y4: 1 | Z4: 1 | AA4: 5 | AB4: 1 | AC4: 1 | AD4: 1 | AE4: 5 | AF4: 1 | AG4: 1 | AH4: 1 | AI4: 5 | AJ4: 1 | AK4: 1 | AL4: 1 | AM4: 5 | AN4: 1 | AO4: 1 | AP4: 1
A5: 0 | B5: 3 | C5: 4 | D5: 4 | E5: 4 | F5: 4 | G5: 4 | H5: 1 | I5: 1 | J5: 1 | K5: 5 | L5: 1 | M5: 1 | N5: 1 | O5: 5 | P5: 1 | Q5: 1 | R5: 1 | S5: 5 | T5: 1 | U5: 1 | V5: 1 | W5: 5 | X5: 1 | Y5: 1 | Z5: 1 | AA5: 5 | AB5: 1 | AC5: 1 | AD5: 1 | AE5: 5 | AF5: 1 | AG5: 1 | AH5: 1 | AI5: 5 | AJ5: 1 | AK5: 1 | AL5: 1 | AM5: 5 | AN5: 1 | AO5: 1 | AP5: 1
A6: 0 | B6: 4 | C6: 4 | D6: 4 | E6: 5 | F6: 5 | G6: 5 | H6: 1 | I6: 1 | J6: 1 | K6: 6 | L6: 1 | M6: 1 | N6: 1 | O6: 6 | P6: 1 | Q6: 1 | R6: 1 | S6: 6 | T6: 1 | U6: 1 | V6: 1 | W6: 6 | X6: 1 | Y6: 1 | Z6: 1 | AA6: 6 | AB6: 1 | AC6: 1 | AD6: 1 | AE6: 6 | AF6: 1 | AG6: 1 | AH6: 1 | AI6: 6 | AJ6: 1 | AK6: 1 | AL6: 1 | AM6: 6 | AN6: 1 | AO6: 1 | AP6: 1
A7: 0 | B7: 5 | C7: 5 | D7: 5 | E7: 6 | F7: 6 | G7: 6 | H7: 1 | I7: 1 | J7: 1 | K7: 7 | L7: 1 | M7: 1 | N7: 1 | O7: 7 | P7: 1 | Q7: 1 | R7: 1 | S7: 7 | T7: 1 | U7: 1 | V7: 1 | W7: 7 | X7: 1 | Y7: 1 | Z7: 1 | AA7: 7 | AB7: 1 | AC7: 1 | AD7: 1 | AE7: 7 | AF7: 1 | AG7: 1 | AH7: 1 | AI7: 7 | AJ7: 1 | AK7: 1 | AL7: 1 | AM7: 7 | AN7: 1 | AO7: 1 | AP7: 1
A8: 0 | B8: 6 | C8: 6 | D8: 6 | E8: 7 | F8: 7 | G8: 7 | H8: 1 | I8: 1 | J8: 1 | K8: 8 | L8: 1 | M8: 1 | N8: 1 | O8: 8 | P8: 1 | Q8: 1 | R8: 1 | S8: 8 | T8: 1 | U8: 1 | V8: 1 | W8: 8 | X8: 1 | Y8: 1 | Z8: 1 | AA8: 8 | AB8: 1 | AC8: 1 | AD8: 1 | AE8: 8 | AF8: 1 | AG8: 1 | AH8: 1 | AI8: 8 | AJ8: 1 | AK8: 1 | AL8: 1 | AM8: 8 | AN8: 1 | AO8: 1 | AP8: 1
A9: 0 | B9: 7 | C9: 7 | D9: 7 | E9: 8 | F9: 8 | G9: 8 | H9: 1 | I9: 1 | J9: 1 | K9: 8 | L9: 1 | M9: 1 | N9: 1 | O9: 8 | P9: 1 | Q9: 1 | R9: 1 | S9: 8 | T9: 1 | U9: 1 | V9: 1 | W9: 8 | X9: 1 | Y9: 1 | Z9: 1 | AA9: 8 | AB9: 1 | AC9: 1 | AD9: 1 | AE9: 8 | AF9: 1 | AG9: 1 | AH9: 1 | AI9: 8 | AJ9: 1 | AK9: 1 | AL9: 1 | AM9: 8 | AN9: 1 | AO9: 1 | AP9: 1
A10: 0 | B10: 8 | C10: 7 | D10: 7 | E10: 9 | F10: 9 | G10: 9 | H10: 1 | I10: 1 | J10: 1 | K10: 9 | L10: 1 | M10: 1 | N10: 1 | O10: 9 | P10: 1 | Q10: 1 | R10: 1 | S10: 9 | T10: 1 | U10: 1 | V10: 1 | W10: 9 | X10: 1 | Y10: 1 | Z10: 1 | AA10: 9 | AB10: 1 | AC10: 1 | AD10: 1 | AE10: 9 | AF10: 1 | AG10: 1 | AH10: 1 | AI10: 9 | AJ10: 1 | AK10: 1 | AL10: 1 | AM10: 9 | AN10: 1 | AO10: 1 | AP10: 1
A11: 0 | B11: 9 | C11: 8 | D11: 8 | E11: 9 | F11: 9 | G11: 9 | H11: 1 | I11: 1 | J11: 1 | K11: 10 | L11: 1 | M11: 1 | N11: 1 | O11: 10 | P11: 1 | Q11: 1 | R11: 1 | S11: 10 | T11: 1 | U11: 1 | V11: 1 | W11: 10 | X11: 1 | Y11: 1 | Z11: 1 | AA11: 10 | AB11: 1 | AC11: 1 | AD11: 1 | AE11: 10 | AF11: 1 | AG11: 1 | AH11: 1 | AI11: 10 | AJ11: 1 | AK11: 1 | AL11: 1 | AM11: 10 | AN11: 1 | AO11: 1 | AP11: 1
A12: 0 | B12: 10 | C12: 9 | D12: 9 | E12: 10 | F12: 10 | G12: 10 | H12: 1 | I12: 1 | J12: 1 | K12: 11 | L12: 1 | M12: 1 | N12: 1 | O12: 11 | P12: 1 | Q12: 1 | R12: 1 | S12: 11 | T12: 1 | U12: 1 | V12: 1 | W12: 11 | X12: 1 | Y12: 1 | Z12: 1 | AA12: 11 | AB12: 1 | AC12: 1 | AD12: 1 | AE12: 11 | AF12: 1 | AG12: 1 | AH12: 1 | AI12: 11 | AJ12: 1 | AK12: 1 | AL12: 1 | AM12: 11 | AN12: 1 | AO12: 1 | AP12: 1
A13: 0 | B13: 11 | C13: 10 | D13: 10 | E13: 11 | F13: 11 | G13: 11 | H13: 1 | I13: 1 | J13: 1 | K13: 11 | L13: 1 | M13: 1 | N13: 1 | O13: 11 | P13: 1 | Q13: 1 | R13: 1 | S13: 11 | T13: 1 | U13: 1 | V13: 1 | W13: 11 | X13: 1 | Y13: 1 | Z13: 1 | AA13: 11 | AB13: 1 | AC13: 1 | AD13: 1 | AE13: 11 | AF13: 1 | AG13: 1 | AH13: 1 | AI13: 11 | AJ13: 1 | AK13: 1 | AL13: 1 | AM13: 11 | AN13: 1 | AO13: 1 | AP13: 1
A14: 0 | B14: 12 | C14: 10 | D14: 10 | E14: 12 | F14: 12 | G14: 12 | H14: 1 | I14: 1 | J14: 1 | K14: 12 | L14: 1 | M14: 1 | N14: 1 | O14: 12 | P14: 1 | Q14: 1 | R14: 1 | S14: 12 | T14: 1 | U14: 1 | V14: 1 | W14: 12 | X14: 1 | Y14: 1 | Z14: 1 | AA14: 12 | AB14: 1 | AC14: 1 | AD14: 1 | AE14: 12 | AF14: 1 | AG14: 1 | AH14: 1 | AI14: 12 | AJ14: 1 | AK14: 1 | AL14: 1 | AM14: 12 | AN14: 1 | AO14: 1 | AP14: 1
... A83: 0 | B83: 81 | C83: 60 | D83: 60 | E83: 99 | F83: 99 | G83: 99 | H83: 1 | I83: 1 | J83: 1 | K83: 99 | L83: 1 | M83: 1 | N83: 1 | O83: 99 | P83: 1 | Q83: 1 | R83: 1 | S83: 99 | T83: 99 | U83: 99 | V83: 99 | W83: 99 | X83: 99 | Y83: 99 | Z83: 99 | AA83: 99 | AB83: 99 | AC83: 99 | AD83: 99 | AE83: 99 | AF83: 99 | AG83: 99 | AH83: 99 | AI83: 99 | AJ83: 99 | AK83: 99 | AL83: 99 | AM83: 99 | AN83: 99 | AO83: 99 | AP83: 99

Sheet SpecialistMastery
A1: string[64] | B1: dword | C1: dword | D1: dword | E1: dword | F1: dword | G1: dword | H1: dword | I1: dword | J1: dword | K1: dword | L1: dword | M1: dword | N1: dword | O1: dword | P1: dword | Q1: dword | R1: dword | S1: dword | T1: dword | U1: dword | V1: dword | W1: dword | X1: dword | Y1: dword | Z1: dword | AA1: dword | AB1: dword | AC1: dword | AD1: dword | AE1: dword | AF1: dword | AG1: dword | AH1: dword | AI1: dword | AJ1: dword | AK1: dword | AL1: dword | AM1: dword | AN1: dword | AO1: dword | AP1: dword | AQ1: END
A2: Name | B2: Lv | C2: MelePT | D2: RangePT | E2: SpecialPT | F2: DefPT | G2: ShieldPT | H2: CraftPt1 | I2: CraftPt2 | J2: CraftPt3 | K2: MeleYch | L2: MeleExp | M2: MeleElitr | N2: MeleMagistr | O2: RangeYch | P2: RangeExp | Q2: RangeElite | R2: RangeMagistr | S2: Dark1 | T2: Dark2 | U2: Dark3 | V2: Dark4 | W2: Holy1 | X2: Holy2 | Y2: Holy3 | Z2: Holy4 | AA2: Fire1 | AB2: Fire2 | AC2: Fire3 | AD2: Fire4 | AE2: Water1 | AF2: Water2 | AG2: Water3 | AH2: Water4 | AI2: Soil1 | AJ2: Soil2 | AK2: Soil3 | AL2: Soil4 | AM2: Wind1 | AN2: Wind2 | AO2: Wind3 | AP2: Wind4
A3: 0 | B3: 1 | C3: 3 | D3: 3 | E3: 3 | F3: 2 | G3: 2 | H3: 99 | I3: 99 | J3: 99 | K3: 2 | L3: 1 | M3: 1 | N3: 1 | O3: 2 | P3: 1 | Q3: 1 | R3: 1 | S3: 3 | T3: 1 | U3: 1 | V3: 1 | W3: 3 | X3: 1 | Y3: 1 | Z3: 1 | AA3: 3 | AB3: 1 | AC3: 1 | AD3: 1 | AE3: 3 | AF3: 1 | AG3: 1 | AH3: 1 | AI3: 3 | AJ3: 1 | AK3: 1 | AL3: 1 | AM3: 3 | AN3: 1 | AO3: 1 | AP3: 1
A4: 0 | B4: 2 | C4: 4 | D4: 4 | E4: 4 | F4: 3 | G4: 3 | H4: 99 | I4: 99 | J4: 99 | K4: 4 | L4: 1 | M4: 1 | N4: 1 | O4: 4 | P4: 1 | Q4: 1 | R4: 1 | S4: 4 | T4: 1 | U4: 1 | V4: 1 | W4: 4 | X4: 1 | Y4: 1 | Z4: 1 | AA4: 4 | AB4: 1 | AC4: 1 | AD4: 1 | AE4: 4 | AF4: 1 | AG4: 1 | AH4: 1 | AI4: 4 | AJ4: 1 | AK4: 1 | AL4: 1 | AM4: 4 | AN4: 1 | AO4: 1 | AP4: 1
A5: 0 | B5: 3 | C5: 5 | D5: 5 | E5: 5 | F5: 4 | G5: 4 | H5: 99 | I5: 99 | J5: 99 | K5: 6 | L5: 1 | M5: 1 | N5: 1 | O5: 6 | P5: 1 | Q5: 1 | R5: 1 | S5: 5 | T5: 1 | U5: 1 | V5: 1 | W5: 5 | X5: 1 | Y5: 1 | Z5: 1 | AA5: 5 | AB5: 1 | AC5: 1 | AD5: 1 | AE5: 5 | AF5: 1 | AG5: 1 | AH5: 1 | AI5: 5 | AJ5: 1 | AK5: 1 | AL5: 1 | AM5: 5 | AN5: 1 | AO5: 1 | AP5: 1
A6: 0 | B6: 4 | C6: 6 | D6: 6 | E6: 6 | F6: 5 | G6: 5 | H6: 99 | I6: 99 | J6: 99 | K6: 8 | L6: 1 | M6: 1 | N6: 1 | O6: 8 | P6: 1 | Q6: 1 | R6: 1 | S6: 6 | T6: 1 | U6: 1 | V6: 1 | W6: 6 | X6: 1 | Y6: 1 | Z6: 1 | AA6: 6 | AB6: 1 | AC6: 1 | AD6: 1 | AE6: 6 | AF6: 1 | AG6: 1 | AH6: 1 | AI6: 6 | AJ6: 1 | AK6: 1 | AL6: 1 | AM6: 6 | AN6: 1 | AO6: 1 | AP6: 1
A7: 0 | B7: 5 | C7: 7 | D7: 7 | E7: 7 | F7: 6 | G7: 6 | H7: 99 | I7: 99 | J7: 99 | K7: 10 | L7: 1 | M7: 1 | N7: 1 | O7: 10 | P7: 1 | Q7: 1 | R7: 1 | S7: 7 | T7: 1 | U7: 1 | V7: 1 | W7: 7 | X7: 1 | Y7: 1 | Z7: 1 | AA7: 7 | AB7: 1 | AC7: 1 | AD7: 1 | AE7: 7 | AF7: 1 | AG7: 1 | AH7: 1 | AI7: 7 | AJ7: 1 | AK7: 1 | AL7: 1 | AM7: 7 | AN7: 1 | AO7: 1 | AP7: 1
A8: 0 | B8: 6 | C8: 8 | D8: 8 | E8: 8 | F8: 7 | G8: 7 | H8: 99 | I8: 99 | J8: 99 | K8: 12 | L8: 1 | M8: 1 | N8: 1 | O8: 12 | P8: 1 | Q8: 1 | R8: 1 | S8: 8 | T8: 1 | U8: 1 | V8: 1 | W8: 8 | X8: 1 | Y8: 1 | Z8: 1 | AA8: 8 | AB8: 1 | AC8: 1 | AD8: 1 | AE8: 8 | AF8: 1 | AG8: 1 | AH8: 1 | AI8: 8 | AJ8: 1 | AK8: 1 | AL8: 1 | AM8: 8 | AN8: 1 | AO8: 1 | AP8: 1
A9: 0 | B9: 7 | C9: 9 | D9: 9 | E9: 9 | F9: 8 | G9: 8 | H9: 99 | I9: 99 | J9: 99 | K9: 15 | L9: 1 | M9: 1 | N9: 1 | O9: 15 | P9: 1 | Q9: 1 | R9: 1 | S9: 9 | T9: 1 | U9: 1 | V9: 1 | W9: 9 | X9: 1 | Y9: 1 | Z9: 1 | AA9: 9 | AB9: 1 | AC9: 1 | AD9: 1 | AE9: 9 | AF9: 1 | AG9: 1 | AH9: 1 | AI9: 9 | AJ9: 1 | AK9: 1 | AL9: 1 | AM9: 9 | AN9: 1 | AO9: 1 | AP9: 1
A10: 0 | B10: 8 | C10: 10 | D10: 10 | E10: 10 | F10: 9 | G10: 9 | H10: 99 | I10: 99 | J10: 99 | K10: 17 | L10: 1 | M10: 1 | N10: 1 | O10: 17 | P10: 1 | Q10: 1 | R10: 1 | S10: 10 | T10: 1 | U10: 1 | V10: 1 | W10: 10 | X10: 1 | Y10: 1 | Z10: 1 | AA10: 10 | AB10: 1 | AC10: 1 | AD10: 1 | AE10: 10 | AF10: 1 | AG10: 1 | AH10: 1 | AI10: 10 | AJ10: 1 | AK10: 1 | AL10: 1 | AM10: 10 | AN10: 1 | AO10: 1 | AP10: 1
A11: 0 | B11: 9 | C11: 12 | D11: 12 | E11: 12 | F11: 9 | G11: 9 | H11: 99 | I11: 99 | J11: 99 | K11: 19 | L11: 1 | M11: 1 | N11: 1 | O11: 19 | P11: 1 | Q11: 1 | R11: 1 | S11: 12 | T11: 1 | U11: 1 | V11: 1 | W11: 12 | X11: 1 | Y11: 1 | Z11: 1 | AA11: 12 | AB11: 1 | AC11: 1 | AD11: 1 | AE11: 12 | AF11: 1 | AG11: 1 | AH11: 1 | AI11: 12 | AJ11: 1 | AK11: 1 | AL11: 1 | AM11: 12 | AN11: 1 | AO11: 1 | AP11: 1
A12: 0 | B12: 10 | C12: 13 | D12: 13 | E12: 13 | F12: 10 | G12: 10 | H12: 99 | I12: 99 | J12: 99 | K12: 21 | L12: 1 | M12: 1 | N12: 1 | O12: 21 | P12: 1 | Q12: 1 | R12: 1 | S12: 13 | T12: 1 | U12: 1 | V12: 1 | W12: 13 | X12: 1 | Y12: 1 | Z12: 1 | AA12: 13 | AB12: 1 | AC12: 1 | AD12: 1 | AE12: 13 | AF12: 1 | AG12: 1 | AH12: 1 | AI12: 13 | AJ12: 1 | AK12: 1 | AL12: 1 | AM12: 13 | AN12: 1 | AO12: 1 | AP12: 1
A13: 0 | B13: 11 | C13: 14 | D13: 14 | E13: 14 | F13: 11 | G13: 11 | H13: 99 | I13: 99 | J13: 99 | K13: 23 | L13: 1 | M13: 1 | N13: 1 | O13: 23 | P13: 1 | Q13: 1 | R13: 1 | S13: 14 | T13: 1 | U13: 1 | V13: 1 | W13: 14 | X13: 1 | Y13: 1 | Z13: 1 | AA13: 14 | AB13: 1 | AC13: 1 | AD13: 1 | AE13: 14 | AF13: 1 | AG13: 1 | AH13: 1 | AI13: 14 | AJ13: 1 | AK13: 1 | AL13: 1 | AM13: 14 | AN13: 1 | AO13: 1 | AP13: 1
A14: 0 | B14: 12 | C14: 15 | D14: 15 | E14: 15 | F14: 12 | G14: 12 | H14: 99 | I14: 99 | J14: 99 | K14: 25 | L14: 1 | M14: 1 | N14: 1 | O14: 25 | P14: 1 | Q14: 1 | R14: 1 | S14: 15 | T14: 1 | U14: 1 | V14: 1 | W14: 15 | X14: 1 | Y14: 1 | Z14: 1 | AA14: 15 | AB14: 1 | AC14: 1 | AD14: 1 | AE14: 15 | AF14: 1 | AG14: 1 | AH14: 1 | AI14: 15 | AJ14: 1 | AK14: 1 | AL14: 1 | AM14: 15 | AN14: 1 | AO14: 1 | AP14: 1
... A83: 0 | B83: 81 | C83: 99 | D83: 99 | E83: 99 | F83: 99 | G83: 99 | H83: 99 | I83: 99 | J83: 99 | K83: 99 | L83: 66 | M83: 1 | N83: 1 | O83: 99 | P83: 66 | Q83: 1 | R83: 1 | S83: 99 | T83: 1 | U83: 1 | V83: 1 | W83: 99 | X83: 1 | Y83: 1 | Z83: 1 | AA83: 99 | AB83: 1 | AC83: 1 | AD83: 1 | AE83: 99 | AF83: 1 | AG83: 1 | AH83: 1 | AI83: 99 | AJ83: 1 | AK83: 1 | AL83: 1 | AM83: 99 | AN83: 1 | AO83: 1 | AP83: 1

Sheet war
A1: byte | B1: byte | C1: byte | D1: byte | E1: byte | F1: byte | G1: byte | H1: byte | I1: byte | J1: byte | K1: byte | L1: byte | M1: byte | N1: byte | O1: byte | P1: byte | Q1: byte | R1: byte | S1: byte | T1: byte | U1: byte | V1: byte | W1: byte | X1: byte | Y1: byte | Z1: byte | AA1: byte | AB1: byte | AC1: byte | AD1: byte | AE1: byte | AF1: byte | AG1: byte | AH1: byte | AI1: byte | AJ1: byte | AK1: byte | AL1: byte | AM1: byte | AN1: byte | AO1: byte | AP1: byte | AQ1: byte | AR1: byte | AS1: byte | AT1: byte | AU1: END
A2: =WarriorMastery!B2 -> Lv | B2: =WarriorMastery!C2 -> MelePT | C2: =WarriorMastery!D2 -> RangePT | D2: =WarriorMastery!E2 -> SpecialPT | E2: Force | F2: =WarriorMastery!G2 -> ShieldPT | G2: =WarriorMastery!F2 -> DefPT | H2: =WarriorMastery!H2 -> CraftPt1 | I2: =WarriorMastery!I2 -> CraftPt2 | J2: =WarriorMastery!J2 -> CraftPt3 | K2: =WarriorMastery!S2 -> Dark1 | L2: =WarriorMastery!T2 -> Dark2 | M2: =WarriorMastery!U2 -> Dark3 | N2: =WarriorMastery!V2 -> Dark4 | O2: =WarriorMastery!W2 -> Holy1 | P2: =WarriorMastery!X2 -> Holy2 | Q2: =WarriorMastery!Y2 -> Holy3 | R2: =WarriorMastery!Z2 -> Holy4 | ... AH2: =WarriorMastery!AP2 -> Wind4 | AI2: =WarriorMastery!K2 -> MeleYch | AJ2: =WarriorMastery!L2 -> MeleExp | AK2: =WarriorMastery!M2 -> MeleElitr | AL2: =WarriorMastery!N2 -> MeleMagistr | AM2: =WarriorMastery!O2 -> RangeYch | AN2: =WarriorMastery!P2 -> RangeExp | AO2: =WarriorMastery!Q2 -> RangeElite | AP2: =WarriorMastery!R2 -> RangeMagistr | AQ2: hz | AR2: hz | AS2: hz | AT2: hz
A3: =WarriorMastery!B3 -> 1 | B3: =WarriorMastery!C3 -> 3 | C3: =WarriorMastery!D3 -> 2 | D3: =WarriorMastery!E3 -> 2 | E3: 99 | F3: =WarriorMastery!G3 -> 2 | G3: =WarriorMastery!F3 -> 2 | H3: =WarriorMastery!H3 -> 1 | I3: =WarriorMastery!I3 -> 1 | J3: =WarriorMastery!J3 -> 1 | K3: =WarriorMastery!S3 -> 2 | L3: =WarriorMastery!T3 -> 1 | M3: =WarriorMastery!U3 -> 1 | N3: =WarriorMastery!V3 -> 1 | O3: =WarriorMastery!W3 -> 2 | P3: =WarriorMastery!X3 -> 1 | Q3: =WarriorMastery!Y3 -> 1 | R3: =WarriorMastery!Z3 -> 1 | ... AH3: =WarriorMastery!AP3 -> 1 | AI3: =WarriorMastery!K3 -> 5 | AJ3: =WarriorMastery!L3 -> 1 | AK3: =WarriorMastery!M3 -> 1 | AL3: =WarriorMastery!N3 -> 1 | AM3: =WarriorMastery!O3 -> 2 | AN3: =WarriorMastery!P3 -> 1 | AO3: =WarriorMastery!Q3 -> 1 | AP3: =WarriorMastery!R3 -> 1 | AQ3: 0 | AR3: 0 | AS3: 0 | AT3: 0
A4: =WarriorMastery!B4 -> 2 | B4: =WarriorMastery!C4 -> 4 | C4: =WarriorMastery!D4 -> 3 | D4: =WarriorMastery!E4 -> 3 | E4: 99 | F4: =WarriorMastery!G4 -> 3 | G4: =WarriorMastery!F4 -> 3 | H4: =WarriorMastery!H4 -> 1 | I4: =WarriorMastery!I4 -> 1 | J4: =WarriorMastery!J4 -> 1 | K4: =WarriorMastery!S4 -> 3 | L4: =WarriorMastery!T4 -> 1 | M4: =WarriorMastery!U4 -> 1 | N4: =WarriorMastery!V4 -> 1 | O4: =WarriorMastery!W4 -> 3 | P4: =WarriorMastery!X4 -> 1 | Q4: =WarriorMastery!Y4 -> 1 | R4: =WarriorMastery!Z4 -> 1 | ... AH4: =WarriorMastery!AP4 -> 1 | AI4: =WarriorMastery!K4 -> 5 | AJ4: =WarriorMastery!L4 -> 1 | AK4: =WarriorMastery!M4 -> 1 | AL4: =WarriorMastery!N4 -> 1 | AM4: =WarriorMastery!O4 -> 3 | AN4: =WarriorMastery!P4 -> 1 | AO4: =WarriorMastery!Q4 -> 1 | AP4: =WarriorMastery!R4 -> 1 | AQ4: 0 | AR4: 0 | AS4: 0 | AT4: 0
A5: =WarriorMastery!B5 -> 3 | B5: =WarriorMastery!C5 -> 5 | C5: =WarriorMastery!D5 -> 4 | D5: =WarriorMastery!E5 -> 4 | E5: 99 | F5: =WarriorMastery!G5 -> 4 | G5: =WarriorMastery!F5 -> 4 | H5: =WarriorMastery!H5 -> 1 | I5: =WarriorMastery!I5 -> 1 | J5: =WarriorMastery!J5 -> 1 | K5: =WarriorMastery!S5 -> 3 | L5: =WarriorMastery!T5 -> 1 | M5: =WarriorMastery!U5 -> 1 | N5: =WarriorMastery!V5 -> 1 | O5: =WarriorMastery!W5 -> 3 | P5: =WarriorMastery!X5 -> 1 | Q5: =WarriorMastery!Y5 -> 1 | R5: =WarriorMastery!Z5 -> 1 | ... AH5: =WarriorMastery!AP5 -> 1 | AI5: =WarriorMastery!K5 -> 5 | AJ5: =WarriorMastery!L5 -> 1 | AK5: =WarriorMastery!M5 -> 1 | AL5: =WarriorMastery!N5 -> 1 | AM5: =WarriorMastery!O5 -> 3 | AN5: =WarriorMastery!P5 -> 1 | AO5: =WarriorMastery!Q5 -> 1 | AP5: =WarriorMastery!R5 -> 1 | AQ5: 0 | AR5: 0 | AS5: 0 | AT5: 0
A6: =WarriorMastery!B6 -> 4 | B6: =WarriorMastery!C6 -> 6 | C6: =WarriorMastery!D6 -> 4 | D6: =WarriorMastery!E6 -> 5 | E6: 99 | F6: =WarriorMastery!G6 -> 5 | G6: =WarriorMastery!F6 -> 5 | H6: =WarriorMastery!H6 -> 1 | I6: =WarriorMastery!I6 -> 1 | J6: =WarriorMastery!J6 -> 1 | K6: =WarriorMastery!S6 -> 4 | L6: =WarriorMastery!T6 -> 1 | M6: =WarriorMastery!U6 -> 1 | N6: =WarriorMastery!V6 -> 1 | O6: =WarriorMastery!W6 -> 4 | P6: =WarriorMastery!X6 -> 1 | Q6: =WarriorMastery!Y6 -> 1 | R6: =WarriorMastery!Z6 -> 1 | ... AH6: =WarriorMastery!AP6 -> 1 | AI6: =WarriorMastery!K6 -> 6 | AJ6: =WarriorMastery!L6 -> 1 | AK6: =WarriorMastery!M6 -> 1 | AL6: =WarriorMastery!N6 -> 1 | AM6: =WarriorMastery!O6 -> 4 | AN6: =WarriorMastery!P6 -> 1 | AO6: =WarriorMastery!Q6 -> 1 | AP6: =WarriorMastery!R6 -> 1 | AQ6: 0 | AR6: 0 | AS6: 0 | AT6: 0
A7: =WarriorMastery!B7 -> 5 | B7: =WarriorMastery!C7 -> 7 | C7: =WarriorMastery!D7 -> 5 | D7: =WarriorMastery!E7 -> 6 | E7: 99 | F7: =WarriorMastery!G7 -> 6 | G7: =WarriorMastery!F7 -> 6 | H7: =WarriorMastery!H7 -> 1 | I7: =WarriorMastery!I7 -> 1 | J7: =WarriorMastery!J7 -> 1 | K7: =WarriorMastery!S7 -> 5 | L7: =WarriorMastery!T7 -> 1 | M7: =WarriorMastery!U7 -> 1 | N7: =WarriorMastery!V7 -> 1 | O7: =WarriorMastery!W7 -> 5 | P7: =WarriorMastery!X7 -> 1 | Q7: =WarriorMastery!Y7 -> 1 | R7: =WarriorMastery!Z7 -> 1 | ... AH7: =WarriorMastery!AP7 -> 1 | AI7: =WarriorMastery!K7 -> 7 | AJ7: =WarriorMastery!L7 -> 1 | AK7: =WarriorMastery!M7 -> 1 | AL7: =WarriorMastery!N7 -> 1 | AM7: =WarriorMastery!O7 -> 5 | AN7: =WarriorMastery!P7 -> 1 | AO7: =WarriorMastery!Q7 -> 1 | AP7: =WarriorMastery!R7 -> 1 | AQ7: 0 | AR7: 0 | AS7: 0 | AT7: 0
A8: =WarriorMastery!B8 -> 6 | B8: =WarriorMastery!C8 -> 8 | C8: =WarriorMastery!D8 -> 6 | D8: =WarriorMastery!E8 -> 7 | E8: 99 | F8: =WarriorMastery!G8 -> 7 | G8: =WarriorMastery!F8 -> 7 | H8: =WarriorMastery!H8 -> 1 | I8: =WarriorMastery!I8 -> 1 | J8: =WarriorMastery!J8 -> 1 | K8: =WarriorMastery!S8 -> 5 | L8: =WarriorMastery!T8 -> 1 | M8: =WarriorMastery!U8 -> 1 | N8: =WarriorMastery!V8 -> 1 | O8: =WarriorMastery!W8 -> 5 | P8: =WarriorMastery!X8 -> 1 | Q8: =WarriorMastery!Y8 -> 1 | R8: =WarriorMastery!Z8 -> 1 | ... AH8: =WarriorMastery!AP8 -> 1 | AI8: =WarriorMastery!K8 -> 8 | AJ8: =WarriorMastery!L8 -> 1 | AK8: =WarriorMastery!M8 -> 1 | AL8: =WarriorMastery!N8 -> 1 | AM8: =WarriorMastery!O8 -> 5 | AN8: =WarriorMastery!P8 -> 1 | AO8: =WarriorMastery!Q8 -> 1 | AP8: =WarriorMastery!R8 -> 1 | AQ8: 0 | AR8: 0 | AS8: 0 | AT8: 0
A9: =WarriorMastery!B9 -> 7 | B9: =WarriorMastery!C9 -> 9 | C9: =WarriorMastery!D9 -> 7 | D9: =WarriorMastery!E9 -> 8 | E9: 99 | F9: =WarriorMastery!G9 -> 8 | G9: =WarriorMastery!F9 -> 8 | H9: =WarriorMastery!H9 -> 1 | I9: =WarriorMastery!I9 -> 1 | J9: =WarriorMastery!J9 -> 1 | K9: =WarriorMastery!S9 -> 5 | L9: =WarriorMastery!T9 -> 1 | M9: =WarriorMastery!U9 -> 1 | N9: =WarriorMastery!V9 -> 1 | O9: =WarriorMastery!W9 -> 5 | P9: =WarriorMastery!X9 -> 1 | Q9: =WarriorMastery!Y9 -> 1 | R9: =WarriorMastery!Z9 -> 1 | ... AH9: =WarriorMastery!AP9 -> 1 | AI9: =WarriorMastery!K9 -> 8 | AJ9: =WarriorMastery!L9 -> 1 | AK9: =WarriorMastery!M9 -> 1 | AL9: =WarriorMastery!N9 -> 1 | AM9: =WarriorMastery!O9 -> 5 | AN9: =WarriorMastery!P9 -> 1 | AO9: =WarriorMastery!Q9 -> 1 | AP9: =WarriorMastery!R9 -> 1 | AQ9: 0 | AR9: 0 | AS9: 0 | AT9: 0
A10: =WarriorMastery!B10 -> 8 | B10: =WarriorMastery!C10 -> 10 | C10: =WarriorMastery!D10 -> 7 | D10: =WarriorMastery!E10 -> 9 | E10: 99 | F10: =WarriorMastery!G10 -> 9 | G10: =WarriorMastery!F10 -> 9 | H10: =WarriorMastery!H10 -> 1 | I10: =WarriorMastery!I10 -> 1 | J10: =WarriorMastery!J10 -> 1 | K10: =WarriorMastery!S10 -> 6 | L10: =WarriorMastery!T10 -> 1 | M10: =WarriorMastery!U10 -> 1 | N10: =WarriorMastery!V10 -> 1 | O10: =WarriorMastery!W10 -> 6 | P10: =WarriorMastery!X10 -> 1 | Q10: =WarriorMastery!Y10 -> 1 | R10: =WarriorMastery!Z10 -> 1 | ... AH10: =WarriorMastery!AP10 -> 1 | AI10: =WarriorMastery!K10 -> 9 | AJ10: =WarriorMastery!L10 -> 1 | AK10: =WarriorMastery!M10 -> 1 | AL10: =WarriorMastery!N10 -> 1 | AM10: =WarriorMastery!O10 -> 6 | AN10: =WarriorMastery!P10 -> 1 | AO10: =WarriorMastery!Q10 -> 1 | AP10: =WarriorMastery!R10 -> 1 | AQ10: 0 | AR10: 0 | AS10: 0 | AT10: 0
A11: =WarriorMastery!B11 -> 9 | B11: =WarriorMastery!C11 -> 12 | C11: =WarriorMastery!D11 -> 8 | D11: =WarriorMastery!E11 -> 9 | E11: 99 | F11: =WarriorMastery!G11 -> 9 | G11: =WarriorMastery!F11 -> 9 | H11: =WarriorMastery!H11 -> 1 | I11: =WarriorMastery!I11 -> 1 | J11: =WarriorMastery!J11 -> 1 | K11: =WarriorMastery!S11 -> 7 | L11: =WarriorMastery!T11 -> 1 | M11: =WarriorMastery!U11 -> 1 | N11: =WarriorMastery!V11 -> 1 | O11: =WarriorMastery!W11 -> 7 | P11: =WarriorMastery!X11 -> 1 | Q11: =WarriorMastery!Y11 -> 1 | R11: =WarriorMastery!Z11 -> 1 | ... AH11: =WarriorMastery!AP11 -> 1 | AI11: =WarriorMastery!K11 -> 10 | AJ11: =WarriorMastery!L11 -> 1 | AK11: =WarriorMastery!M11 -> 1 | AL11: =WarriorMastery!N11 -> 1 | AM11: =WarriorMastery!O11 -> 7 | AN11: =WarriorMastery!P11 -> 1 | AO11: =WarriorMastery!Q11 -> 1 | AP11: =WarriorMastery!R11 -> 1 | AQ11: 0 | AR11: 0 | AS11: 0 | AT11: 0
A12: =WarriorMastery!B12 -> 10 | B12: =WarriorMastery!C12 -> 13 | C12: =WarriorMastery!D12 -> 9 | D12: =WarriorMastery!E12 -> 10 | E12: 99 | F12: =WarriorMastery!G12 -> 10 | G12: =WarriorMastery!F12 -> 10 | H12: =WarriorMastery!H12 -> 1 | I12: =WarriorMastery!I12 -> 1 | J12: =WarriorMastery!J12 -> 1 | K12: =WarriorMastery!S12 -> 7 | L12: =WarriorMastery!T12 -> 1 | M12: =WarriorMastery!U12 -> 1 | N12: =WarriorMastery!V12 -> 1 | O12: =WarriorMastery!W12 -> 7 | P12: =WarriorMastery!X12 -> 1 | Q12: =WarriorMastery!Y12 -> 1 | R12: =WarriorMastery!Z12 -> 1 | ... AH12: =WarriorMastery!AP12 -> 1 | AI12: =WarriorMastery!K12 -> 11 | AJ12: =WarriorMastery!L12 -> 1 | AK12: =WarriorMastery!M12 -> 1 | AL12: =WarriorMastery!N12 -> 1 | AM12: =WarriorMastery!O12 -> 7 | AN12: =WarriorMastery!P12 -> 1 | AO12: =WarriorMastery!Q12 -> 1 | AP12: =WarriorMastery!R12 -> 1 | AQ12: 0 | AR12: 0 | AS12: 0 | AT12: 0
A13: =WarriorMastery!B13 -> 11 | B13: =WarriorMastery!C13 -> 14 | C13: =WarriorMastery!D13 -> 10 | D13: =WarriorMastery!E13 -> 11 | E13: 99 | F13: =WarriorMastery!G13 -> 11 | G13: =WarriorMastery!F13 -> 11 | H13: =WarriorMastery!H13 -> 1 | I13: =WarriorMastery!I13 -> 1 | J13: =WarriorMastery!J13 -> 1 | K13: =WarriorMastery!S13 -> 7 | L13: =WarriorMastery!T13 -> 1 | M13: =WarriorMastery!U13 -> 1 | N13: =WarriorMastery!V13 -> 1 | O13: =WarriorMastery!W13 -> 7 | P13: =WarriorMastery!X13 -> 1 | Q13: =WarriorMastery!Y13 -> 1 | R13: =WarriorMastery!Z13 -> 1 | ... AH13: =WarriorMastery!AP13 -> 1 | AI13: =WarriorMastery!K13 -> 11 | AJ13: =WarriorMastery!L13 -> 1 | AK13: =WarriorMastery!M13 -> 1 | AL13: =WarriorMastery!N13 -> 1 | AM13: =WarriorMastery!O13 -> 7 | AN13: =WarriorMastery!P13 -> 1 | AO13: =WarriorMastery!Q13 -> 1 | AP13: =WarriorMastery!R13 -> 1 | AQ13: 0 | AR13: 0 | AS13: 0 | AT13: 0
A14: =WarriorMastery!B14 -> 12 | B14: =WarriorMastery!C14 -> 15 | C14: =WarriorMastery!D14 -> 10 | D14: =WarriorMastery!E14 -> 12 | E14: 99 | F14: =WarriorMastery!G14 -> 12 | G14: =WarriorMastery!F14 -> 12 | H14: =WarriorMastery!H14 -> 1 | I14: =WarriorMastery!I14 -> 1 | J14: =WarriorMastery!J14 -> 1 | K14: =WarriorMastery!S14 -> 8 | L14: =WarriorMastery!T14 -> 1 | M14: =WarriorMastery!U14 -> 1 | N14: =WarriorMastery!V14 -> 1 | O14: =WarriorMastery!W14 -> 8 | P14: =WarriorMastery!X14 -> 1 | Q14: =WarriorMastery!Y14 -> 1 | R14: =WarriorMastery!Z14 -> 1 | ... AH14: =WarriorMastery!AP14 -> 1 | AI14: =WarriorMastery!K14 -> 12 | AJ14: =WarriorMastery!L14 -> 1 | AK14: =WarriorMastery!M14 -> 1 | AL14: =WarriorMastery!N14 -> 1 | AM14: =WarriorMastery!O14 -> 8 | AN14: =WarriorMastery!P14 -> 1 | AO14: =WarriorMastery!Q14 -> 1 | AP14: =WarriorMastery!R14 -> 1 | AQ14: 0 | AR14: 0 | AS14: 0 | AT14: 0
... A83: =WarriorMastery!B83 -> 81 | B83: =WarriorMastery!C83 -> 99 | C83: =WarriorMastery!D83 -> 60 | D83: =WarriorMastery!E83 -> 99 | E83: 99 | F83: =WarriorMastery!G83 -> 99 | G83: =WarriorMastery!F83 -> 99 | H83: =WarriorMastery!H83 -> 1 | I83: =WarriorMastery!I83 -> 1 | J83: =WarriorMastery!J83 -> 1 | K83: =WarriorMastery!S83 -> 66 | L83: =WarriorMastery!T83 -> 1 | M83: =WarriorMastery!U83 -> 1 | N83: =WarriorMastery!V83 -> 1 | O83: =WarriorMastery!W83 -> 66 | P83: =WarriorMastery!X83 -> 1 | Q83: =WarriorMastery!Y83 -> 1 | R83: =WarriorMastery!Z83 -> 1 | ... AH83: =WarriorMastery!AP83 -> 1 | AI83: =WarriorMastery!K83 -> 99 | AJ83: =WarriorMastery!L83 -> 99 | AK83: =WarriorMastery!M83 -> 99 | AL83: =WarriorMastery!N83 -> 99 | AM83: =WarriorMastery!O83 -> 66 | AN83: =WarriorMastery!P83 -> 1 | AO83: =WarriorMastery!Q83 -> 1 | AP83: =WarriorMastery!R83 -> 1 | AQ83: 0 | AR83: 0 | AS83: 0 | AT83: 0

Sheet ran
A1: byte | B1: byte | C1: byte | D1: byte | E1: byte | F1: byte | G1: byte | H1: byte | I1: byte | J1: byte | K1: byte | L1: byte | M1: byte | N1: byte | O1: byte | P1: byte | Q1: byte | R1: byte | S1: byte | T1: byte | U1: byte | V1: byte | W1: byte | X1: byte | Y1: byte | Z1: byte | AA1: byte | AB1: byte | AC1: byte | AD1: byte | AE1: byte | AF1: byte | AG1: byte | AH1: byte | AI1: byte | AJ1: byte | AK1: byte | AL1: byte | AM1: byte | AN1: byte | AO1: byte | AP1: byte | AQ1: byte | AR1: byte | AS1: byte | AT1: byte | AU1: END
A2: =RangerMastery!B2 -> Lv | B2: =RangerMastery!C2 -> MelePT | C2: =RangerMastery!D2 -> RangePT | D2: =RangerMastery!E2 -> SpecialPT | E2: Force | F2: =RangerMastery!G2 -> ShieldPT | G2: =RangerMastery!F2 -> DefPT | H2: =RangerMastery!H2 -> CraftPt1 | I2: =RangerMastery!I2 -> CraftPt2 | J2: =RangerMastery!J2 -> CraftPt3 | K2: =RangerMastery!S2 -> Dark1 | L2: =RangerMastery!T2 -> Dark2 | M2: =RangerMastery!U2 -> Dark3 | N2: =RangerMastery!V2 -> Dark4 | O2: =RangerMastery!W2 -> Holy1 | P2: =RangerMastery!X2 -> Holy2 | Q2: =RangerMastery!Y2 -> Holy3 | R2: =RangerMastery!Z2 -> Holy4 | ... AH2: =RangerMastery!AP2 -> Wind4 | AI2: =RangerMastery!K2 -> MeleYch | AJ2: =RangerMastery!L2 -> MeleExp | AK2: =RangerMastery!M2 -> MeleElitr | AL2: =RangerMastery!N2 -> MeleMagistr | AM2: =RangerMastery!O2 -> RangeYch | AN2: =RangerMastery!P2 -> RangeExp | AO2: =RangerMastery!Q2 -> RangeElite | AP2: =RangerMastery!R2 -> RangeMagistr | AQ2: hz | AR2: hz | AS2: hz | AT2: hz
A3: =RangerMastery!B3 -> 1 | B3: =RangerMastery!C3 -> 2 | C3: =RangerMastery!D3 -> 3 | D3: =RangerMastery!E3 -> 2 | E3: 99 | F3: =RangerMastery!G3 -> 2 | G3: =RangerMastery!F3 -> 2 | H3: =RangerMastery!H3 -> 1 | I3: =RangerMastery!I3 -> 1 | J3: =RangerMastery!J3 -> 1 | K3: =RangerMastery!S3 -> 2 | L3: =RangerMastery!T3 -> 1 | M3: =RangerMastery!U3 -> 1 | N3: =RangerMastery!V3 -> 1 | O3: =RangerMastery!W3 -> 2 | P3: =RangerMastery!X3 -> 1 | Q3: =RangerMastery!Y3 -> 1 | R3: =RangerMastery!Z3 -> 1 | ... AH3: =RangerMastery!AP3 -> 1 | AI3: =RangerMastery!K3 -> 2 | AJ3: =RangerMastery!L3 -> 1 | AK3: =RangerMastery!M3 -> 1 | AL3: =RangerMastery!N3 -> 1 | AM3: =RangerMastery!O3 -> 5 | AN3: =RangerMastery!P3 -> 1 | AO3: =RangerMastery!Q3 -> 1 | AP3: =RangerMastery!R3 -> 1 | AQ3: 0 | AR3: 0 | AS3: 0 | AT3: 0
A4: =RangerMastery!B4 -> 2 | B4: =RangerMastery!C4 -> 3 | C4: =RangerMastery!D4 -> 4 | D4: =RangerMastery!E4 -> 3 | E4: 99 | F4: =RangerMastery!G4 -> 3 | G4: =RangerMastery!F4 -> 3 | H4: =RangerMastery!H4 -> 1 | I4: =RangerMastery!I4 -> 1 | J4: =RangerMastery!J4 -> 1 | K4: =RangerMastery!S4 -> 3 | L4: =RangerMastery!T4 -> 1 | M4: =RangerMastery!U4 -> 1 | N4: =RangerMastery!V4 -> 1 | O4: =RangerMastery!W4 -> 3 | P4: =RangerMastery!X4 -> 1 | Q4: =RangerMastery!Y4 -> 1 | R4: =RangerMastery!Z4 -> 1 | ... AH4: =RangerMastery!AP4 -> 1 | AI4: =RangerMastery!K4 -> 3 | AJ4: =RangerMastery!L4 -> 1 | AK4: =RangerMastery!M4 -> 1 | AL4: =RangerMastery!N4 -> 1 | AM4: =RangerMastery!O4 -> 5 | AN4: =RangerMastery!P4 -> 1 | AO4: =RangerMastery!Q4 -> 1 | AP4: =RangerMastery!R4 -> 1 | AQ4: 0 | AR4: 0 | AS4: 0 | AT4: 0
A5: =RangerMastery!B5 -> 3 | B5: =RangerMastery!C5 -> 4 | C5: =RangerMastery!D5 -> 5 | D5: =RangerMastery!E5 -> 4 | E5: 99 | F5: =RangerMastery!G5 -> 3 | G5: =RangerMastery!F5 -> 4 | H5: =RangerMastery!H5 -> 1 | I5: =RangerMastery!I5 -> 1 | J5: =RangerMastery!J5 -> 1 | K5: =RangerMastery!S5 -> 3 | L5: =RangerMastery!T5 -> 1 | M5: =RangerMastery!U5 -> 1 | N5: =RangerMastery!V5 -> 1 | O5: =RangerMastery!W5 -> 3 | P5: =RangerMastery!X5 -> 1 | Q5: =RangerMastery!Y5 -> 1 | R5: =RangerMastery!Z5 -> 1 | ... AH5: =RangerMastery!AP5 -> 1 | AI5: =RangerMastery!K5 -> 3 | AJ5: =RangerMastery!L5 -> 1 | AK5: =RangerMastery!M5 -> 1 | AL5: =RangerMastery!N5 -> 1 | AM5: =RangerMastery!O5 -> 5 | AN5: =RangerMastery!P5 -> 1 | AO5: =RangerMastery!Q5 -> 1 | AP5: =RangerMastery!R5 -> 1 | AQ5: 0 | AR5: 0 | AS5: 0 | AT5: 0
A6: =RangerMastery!B6 -> 4 | B6: =RangerMastery!C6 -> 4 | C6: =RangerMastery!D6 -> 6 | D6: =RangerMastery!E6 -> 5 | E6: 99 | F6: =RangerMastery!G6 -> 4 | G6: =RangerMastery!F6 -> 5 | H6: =RangerMastery!H6 -> 1 | I6: =RangerMastery!I6 -> 1 | J6: =RangerMastery!J6 -> 1 | K6: =RangerMastery!S6 -> 4 | L6: =RangerMastery!T6 -> 1 | M6: =RangerMastery!U6 -> 1 | N6: =RangerMastery!V6 -> 1 | O6: =RangerMastery!W6 -> 4 | P6: =RangerMastery!X6 -> 1 | Q6: =RangerMastery!Y6 -> 1 | R6: =RangerMastery!Z6 -> 1 | ... AH6: =RangerMastery!AP6 -> 1 | AI6: =RangerMastery!K6 -> 4 | AJ6: =RangerMastery!L6 -> 1 | AK6: =RangerMastery!M6 -> 1 | AL6: =RangerMastery!N6 -> 1 | AM6: =RangerMastery!O6 -> 6 | AN6: =RangerMastery!P6 -> 1 | AO6: =RangerMastery!Q6 -> 1 | AP6: =RangerMastery!R6 -> 1 | AQ6: 0 | AR6: 0 | AS6: 0 | AT6: 0
A7: =RangerMastery!B7 -> 5 | B7: =RangerMastery!C7 -> 5 | C7: =RangerMastery!D7 -> 7 | D7: =RangerMastery!E7 -> 6 | E7: 99 | F7: =RangerMastery!G7 -> 4 | G7: =RangerMastery!F7 -> 6 | H7: =RangerMastery!H7 -> 1 | I7: =RangerMastery!I7 -> 1 | J7: =RangerMastery!J7 -> 1 | K7: =RangerMastery!S7 -> 5 | L7: =RangerMastery!T7 -> 1 | M7: =RangerMastery!U7 -> 1 | N7: =RangerMastery!V7 -> 1 | O7: =RangerMastery!W7 -> 5 | P7: =RangerMastery!X7 -> 1 | Q7: =RangerMastery!Y7 -> 1 | R7: =RangerMastery!Z7 -> 1 | ... AH7: =RangerMastery!AP7 -> 1 | AI7: =RangerMastery!K7 -> 5 | AJ7: =RangerMastery!L7 -> 1 | AK7: =RangerMastery!M7 -> 1 | AL7: =RangerMastery!N7 -> 1 | AM7: =RangerMastery!O7 -> 7 | AN7: =RangerMastery!P7 -> 1 | AO7: =RangerMastery!Q7 -> 1 | AP7: =RangerMastery!R7 -> 1 | AQ7: 0 | AR7: 0 | AS7: 0 | AT7: 0
A8: =RangerMastery!B8 -> 6 | B8: =RangerMastery!C8 -> 6 | C8: =RangerMastery!D8 -> 8 | D8: =RangerMastery!E8 -> 7 | E8: 99 | F8: =RangerMastery!G8 -> 5 | G8: =RangerMastery!F8 -> 7 | H8: =RangerMastery!H8 -> 1 | I8: =RangerMastery!I8 -> 1 | J8: =RangerMastery!J8 -> 1 | K8: =RangerMastery!S8 -> 5 | L8: =RangerMastery!T8 -> 1 | M8: =RangerMastery!U8 -> 1 | N8: =RangerMastery!V8 -> 1 | O8: =RangerMastery!W8 -> 5 | P8: =RangerMastery!X8 -> 1 | Q8: =RangerMastery!Y8 -> 1 | R8: =RangerMastery!Z8 -> 1 | ... AH8: =RangerMastery!AP8 -> 1 | AI8: =RangerMastery!K8 -> 5 | AJ8: =RangerMastery!L8 -> 1 | AK8: =RangerMastery!M8 -> 1 | AL8: =RangerMastery!N8 -> 1 | AM8: =RangerMastery!O8 -> 8 | AN8: =RangerMastery!P8 -> 1 | AO8: =RangerMastery!Q8 -> 1 | AP8: =RangerMastery!R8 -> 1 | AQ8: 0 | AR8: 0 | AS8: 0 | AT8: 0
A9: =RangerMastery!B9 -> 7 | B9: =RangerMastery!C9 -> 7 | C9: =RangerMastery!D9 -> 9 | D9: =RangerMastery!E9 -> 8 | E9: 99 | F9: =RangerMastery!G9 -> 6 | G9: =RangerMastery!F9 -> 8 | H9: =RangerMastery!H9 -> 1 | I9: =RangerMastery!I9 -> 1 | J9: =RangerMastery!J9 -> 1 | K9: =RangerMastery!S9 -> 5 | L9: =RangerMastery!T9 -> 1 | M9: =RangerMastery!U9 -> 1 | N9: =RangerMastery!V9 -> 1 | O9: =RangerMastery!W9 -> 5 | P9: =RangerMastery!X9 -> 1 | Q9: =RangerMastery!Y9 -> 1 | R9: =RangerMastery!Z9 -> 1 | ... AH9: =RangerMastery!AP9 -> 1 | AI9: =RangerMastery!K9 -> 5 | AJ9: =RangerMastery!L9 -> 1 | AK9: =RangerMastery!M9 -> 1 | AL9: =RangerMastery!N9 -> 1 | AM9: =RangerMastery!O9 -> 8 | AN9: =RangerMastery!P9 -> 1 | AO9: =RangerMastery!Q9 -> 1 | AP9: =RangerMastery!R9 -> 1 | AQ9: 0 | AR9: 0 | AS9: 0 | AT9: 0
A10: =RangerMastery!B10 -> 8 | B10: =RangerMastery!C10 -> 7 | C10: =RangerMastery!D10 -> 10 | D10: =RangerMastery!E10 -> 9 | E10: 99 | F10: =RangerMastery!G10 -> 6 | G10: =RangerMastery!F10 -> 9 | H10: =RangerMastery!H10 -> 1 | I10: =RangerMastery!I10 -> 1 | J10: =RangerMastery!J10 -> 1 | K10: =RangerMastery!S10 -> 6 | L10: =RangerMastery!T10 -> 1 | M10: =RangerMastery!U10 -> 1 | N10: =RangerMastery!V10 -> 1 | O10: =RangerMastery!W10 -> 6 | P10: =RangerMastery!X10 -> 1 | Q10: =RangerMastery!Y10 -> 1 | R10: =RangerMastery!Z10 -> 1 | ... AH10: =RangerMastery!AP10 -> 1 | AI10: =RangerMastery!K10 -> 6 | AJ10: =RangerMastery!L10 -> 1 | AK10: =RangerMastery!M10 -> 1 | AL10: =RangerMastery!N10 -> 1 | AM10: =RangerMastery!O10 -> 9 | AN10: =RangerMastery!P10 -> 1 | AO10: =RangerMastery!Q10 -> 1 | AP10: =RangerMastery!R10 -> 1 | AQ10: 0 | AR10: 0 | AS10: 0 | AT10: 0
A11: =RangerMastery!B11 -> 9 | B11: =RangerMastery!C11 -> 8 | C11: =RangerMastery!D11 -> 12 | D11: =RangerMastery!E11 -> 9 | E11: 99 | F11: =RangerMastery!G11 -> 7 | G11: =RangerMastery!F11 -> 9 | H11: =RangerMastery!H11 -> 1 | I11: =RangerMastery!I11 -> 1 | J11: =RangerMastery!J11 -> 1 | K11: =RangerMastery!S11 -> 7 | L11: =RangerMastery!T11 -> 1 | M11: =RangerMastery!U11 -> 1 | N11: =RangerMastery!V11 -> 1 | O11: =RangerMastery!W11 -> 7 | P11: =RangerMastery!X11 -> 1 | Q11: =RangerMastery!Y11 -> 1 | R11: =RangerMastery!Z11 -> 1 | ... AH11: =RangerMastery!AP11 -> 1 | AI11: =RangerMastery!K11 -> 7 | AJ11: =RangerMastery!L11 -> 1 | AK11: =RangerMastery!M11 -> 1 | AL11: =RangerMastery!N11 -> 1 | AM11: =RangerMastery!O11 -> 10 | AN11: =RangerMastery!P11 -> 1 | AO11: =RangerMastery!Q11 -> 1 | AP11: =RangerMastery!R11 -> 1 | AQ11: 0 | AR11: 0 | AS11: 0 | AT11: 0
A12: =RangerMastery!B12 -> 10 | B12: =RangerMastery!C12 -> 9 | C12: =RangerMastery!D12 -> 13 | D12: =RangerMastery!E12 -> 10 | E12: 99 | F12: =RangerMastery!G12 -> 7 | G12: =RangerMastery!F12 -> 10 | H12: =RangerMastery!H12 -> 1 | I12: =RangerMastery!I12 -> 1 | J12: =RangerMastery!J12 -> 1 | K12: =RangerMastery!S12 -> 7 | L12: =RangerMastery!T12 -> 1 | M12: =RangerMastery!U12 -> 1 | N12: =RangerMastery!V12 -> 1 | O12: =RangerMastery!W12 -> 7 | P12: =RangerMastery!X12 -> 1 | Q12: =RangerMastery!Y12 -> 1 | R12: =RangerMastery!Z12 -> 1 | ... AH12: =RangerMastery!AP12 -> 1 | AI12: =RangerMastery!K12 -> 7 | AJ12: =RangerMastery!L12 -> 1 | AK12: =RangerMastery!M12 -> 1 | AL12: =RangerMastery!N12 -> 1 | AM12: =RangerMastery!O12 -> 11 | AN12: =RangerMastery!P12 -> 1 | AO12: =RangerMastery!Q12 -> 1 | AP12: =RangerMastery!R12 -> 1 | AQ12: 0 | AR12: 0 | AS12: 0 | AT12: 0
A13: =RangerMastery!B13 -> 11 | B13: =RangerMastery!C13 -> 10 | C13: =RangerMastery!D13 -> 14 | D13: =RangerMastery!E13 -> 11 | E13: 99 | F13: =RangerMastery!G13 -> 8 | G13: =RangerMastery!F13 -> 11 | H13: =RangerMastery!H13 -> 1 | I13: =RangerMastery!I13 -> 1 | J13: =RangerMastery!J13 -> 1 | K13: =RangerMastery!S13 -> 7 | L13: =RangerMastery!T13 -> 1 | M13: =RangerMastery!U13 -> 1 | N13: =RangerMastery!V13 -> 1 | O13: =RangerMastery!W13 -> 7 | P13: =RangerMastery!X13 -> 1 | Q13: =RangerMastery!Y13 -> 1 | R13: =RangerMastery!Z13 -> 1 | ... AH13: =RangerMastery!AP13 -> 1 | AI13: =RangerMastery!K13 -> 7 | AJ13: =RangerMastery!L13 -> 1 | AK13: =RangerMastery!M13 -> 1 | AL13: =RangerMastery!N13 -> 1 | AM13: =RangerMastery!O13 -> 11 | AN13: =RangerMastery!P13 -> 1 | AO13: =RangerMastery!Q13 -> 1 | AP13: =RangerMastery!R13 -> 1 | AQ13: 0 | AR13: 0 | AS13: 0 | AT13: 0
A14: =RangerMastery!B14 -> 12 | B14: =RangerMastery!C14 -> 10 | C14: =RangerMastery!D14 -> 15 | D14: =RangerMastery!E14 -> 12 | E14: 99 | F14: =RangerMastery!G14 -> 9 | G14: =RangerMastery!F14 -> 12 | H14: =RangerMastery!H14 -> 1 | I14: =RangerMastery!I14 -> 1 | J14: =RangerMastery!J14 -> 1 | K14: =RangerMastery!S14 -> 8 | L14: =RangerMastery!T14 -> 1 | M14: =RangerMastery!U14 -> 1 | N14: =RangerMastery!V14 -> 1 | O14: =RangerMastery!W14 -> 8 | P14: =RangerMastery!X14 -> 1 | Q14: =RangerMastery!Y14 -> 1 | R14: =RangerMastery!Z14 -> 1 | ... AH14: =RangerMastery!AP14 -> 1 | AI14: =RangerMastery!K14 -> 8 | AJ14: =RangerMastery!L14 -> 1 | AK14: =RangerMastery!M14 -> 1 | AL14: =RangerMastery!N14 -> 1 | AM14: =RangerMastery!O14 -> 12 | AN14: =RangerMastery!P14 -> 1 | AO14: =RangerMastery!Q14 -> 1 | AP14: =RangerMastery!R14 -> 1 | AQ14: 0 | AR14: 0 | AS14: 0 | AT14: 0
... A83: =RangerMastery!B83 -> 81 | B83: =RangerMastery!C83 -> 60 | C83: =RangerMastery!D83 -> 99 | D83: =RangerMastery!E83 -> 99 | E83: 99 | F83: =RangerMastery!G83 -> 60 | G83: =RangerMastery!F83 -> 99 | H83: =RangerMastery!H83 -> 1 | I83: =RangerMastery!I83 -> 1 | J83: =RangerMastery!J83 -> 1 | K83: =RangerMastery!S83 -> 66 | L83: =RangerMastery!T83 -> 1 | M83: =RangerMastery!U83 -> 1 | N83: =RangerMastery!V83 -> 1 | O83: =RangerMastery!W83 -> 66 | P83: =RangerMastery!X83 -> 1 | Q83: =RangerMastery!Y83 -> 1 | R83: =RangerMastery!Z83 -> 1 | ... AH83: =RangerMastery!AP83 -> 1 | AI83: =RangerMastery!K83 -> 66 | AJ83: =RangerMastery!L83 -> 1 | AK83: =RangerMastery!M83 -> 1 | AL83: =RangerMastery!N83 -> 1 | AM83: =RangerMastery!O83 -> 99 | AN83: =RangerMastery!P83 -> 99 | AO83: =RangerMastery!Q83 -> 99 | AP83: =RangerMastery!R83 -> 5 | AQ83: 0 | AR83: 0 | AS83: 0 | AT83: 0

Sheet spr
A1: byte | B1: byte | C1: byte | D1: byte | E1: byte | F1: byte | G1: byte | H1: byte | I1: byte | J1: byte | K1: byte | L1: byte | M1: byte | N1: byte | O1: byte | P1: byte | Q1: byte | R1: byte | S1: byte | T1: byte | U1: byte | V1: byte | W1: byte | X1: byte | Y1: byte | Z1: byte | AA1: byte | AB1: byte | AC1: byte | AD1: byte | AE1: byte | AF1: byte | AG1: byte | AH1: byte | AI1: byte | AJ1: byte | AK1: byte | AL1: byte | AM1: byte | AN1: byte | AO1: byte | AP1: byte | AQ1: byte | AR1: byte | AS1: byte | AT1: byte | AU1: END
A2: =SpiriutalistMastery!B2 -> Lv | B2: =SpiriutalistMastery!C2 -> MelePT | C2: =SpiriutalistMastery!D2 -> RangePT | D2: =SpiriutalistMastery!E2 -> SpecialPT | E2: Force | F2: =SpiriutalistMastery!G2 -> ShieldPT | G2: =SpiriutalistMastery!F2 -> DefPT | H2: =SpiriutalistMastery!H2 -> CraftPt1 | I2: =SpiriutalistMastery!I2 -> CraftPt2 | J2: =SpiriutalistMastery!J2 -> CraftPt3 | K2: =SpiriutalistMastery!S2 -> Dark1 | L2: =SpiriutalistMastery!T2 -> Dark2 | M2: =SpiriutalistMastery!U2 -> Dark3 | N2: =SpiriutalistMastery!V2 -> Dark4 | O2: =SpiriutalistMastery!W2 -> Holy1 | P2: =SpiriutalistMastery!X2 -> Holy2 | Q2: =SpiriutalistMastery!Y2 -> Holy3 | R2: =SpiriutalistMastery!Z2 -> Holy4 | ... AH2: =SpiriutalistMastery!AP2 -> Wind4 | AI2: =SpiriutalistMastery!K2 -> MeleYch | AJ2: =SpiriutalistMastery!L2 -> MeleExp | AK2: =SpiriutalistMastery!M2 -> MeleElitr | AL2: =SpiriutalistMastery!N2 -> MeleMagistr | AM2: =SpiriutalistMastery!O2 -> RangeYch | AN2: =SpiriutalistMastery!P2 -> RangeExp | AO2: =SpiriutalistMastery!Q2 -> RangeElite | AP2: =SpiriutalistMastery!R2 -> RangeMagistr | AQ2: hz | AR2: hz | AS2: hz | AT2: hz
A3: =SpiriutalistMastery!B3 -> 1 | B3: =SpiriutalistMastery!C3 -> 2 | C3: =SpiriutalistMastery!D3 -> 2 | D3: =SpiriutalistMastery!E3 -> 2 | E3: 99 | F3: =SpiriutalistMastery!G3 -> 2 | G3: =SpiriutalistMastery!F3 -> 2 | H3: =SpiriutalistMastery!H3 -> 1 | I3: =SpiriutalistMastery!I3 -> 1 | J3: =SpiriutalistMastery!J3 -> 1 | K3: =SpiriutalistMastery!S3 -> 5 | L3: =SpiriutalistMastery!T3 -> 1 | M3: =SpiriutalistMastery!U3 -> 1 | N3: =SpiriutalistMastery!V3 -> 1 | O3: =SpiriutalistMastery!W3 -> 5 | P3: =SpiriutalistMastery!X3 -> 1 | Q3: =SpiriutalistMastery!Y3 -> 1 | R3: =SpiriutalistMastery!Z3 -> 1 | ... AH3: =SpiriutalistMastery!AP3 -> 1 | AI3: =SpiriutalistMastery!K3 -> 2 | AJ3: =SpiriutalistMastery!L3 -> 1 | AK3: =SpiriutalistMastery!M3 -> 1 | AL3: =SpiriutalistMastery!N3 -> 1 | AM3: =SpiriutalistMastery!O3 -> 2 | AN3: =SpiriutalistMastery!P3 -> 1 | AO3: =SpiriutalistMastery!Q3 -> 1 | AP3: =SpiriutalistMastery!R3 -> 1 | AQ3: 0 | AR3: 0 | AS3: 0 | AT3: 0
A4: =SpiriutalistMastery!B4 -> 2 | B4: =SpiriutalistMastery!C4 -> 3 | C4: =SpiriutalistMastery!D4 -> 3 | D4: =SpiriutalistMastery!E4 -> 3 | E4: 99 | F4: =SpiriutalistMastery!G4 -> 3 | G4: =SpiriutalistMastery!F4 -> 3 | H4: =SpiriutalistMastery!H4 -> 1 | I4: =SpiriutalistMastery!I4 -> 1 | J4: =SpiriutalistMastery!J4 -> 1 | K4: =SpiriutalistMastery!S4 -> 5 | L4: =SpiriutalistMastery!T4 -> 1 | M4: =SpiriutalistMastery!U4 -> 1 | N4: =SpiriutalistMastery!V4 -> 1 | O4: =SpiriutalistMastery!W4 -> 5 | P4: =SpiriutalistMastery!X4 -> 1 | Q4: =SpiriutalistMastery!Y4 -> 1 | R4: =SpiriutalistMastery!Z4 -> 1 | ... AH4: =SpiriutalistMastery!AP4 -> 1 | AI4: =SpiriutalistMastery!K4 -> 4 | AJ4: =SpiriutalistMastery!L4 -> 1 | AK4: =SpiriutalistMastery!M4 -> 1 | AL4: =SpiriutalistMastery!N4 -> 1 | AM4: =SpiriutalistMastery!O4 -> 4 | AN4: =SpiriutalistMastery!P4 -> 1 | AO4: =SpiriutalistMastery!Q4 -> 1 | AP4: =SpiriutalistMastery!R4 -> 1 | AQ4: 0 | AR4: 0 | AS4: 0 | AT4: 0
A5: =SpiriutalistMastery!B5 -> 3 | B5: =SpiriutalistMastery!C5 -> 4 | C5: =SpiriutalistMastery!D5 -> 4 | D5: =SpiriutalistMastery!E5 -> 4 | E5: 99 | F5: =SpiriutalistMastery!G5 -> 4 | G5: =SpiriutalistMastery!F5 -> 4 | H5: =SpiriutalistMastery!H5 -> 1 | I5: =SpiriutalistMastery!I5 -> 1 | J5: =SpiriutalistMastery!J5 -> 1 | K5: =SpiriutalistMastery!S5 -> 5 | L5: =SpiriutalistMastery!T5 -> 1 | M5: =SpiriutalistMastery!U5 -> 1 | N5: =SpiriutalistMastery!V5 -> 1 | O5: =SpiriutalistMastery!W5 -> 5 | P5: =SpiriutalistMastery!X5 -> 1 | Q5: =SpiriutalistMastery!Y5 -> 1 | R5: =SpiriutalistMastery!Z5 -> 1 | ... AH5: =SpiriutalistMastery!AP5 -> 1 | AI5: =SpiriutalistMastery!K5 -> 5 | AJ5: =SpiriutalistMastery!L5 -> 1 | AK5: =SpiriutalistMastery!M5 -> 1 | AL5: =SpiriutalistMastery!N5 -> 1 | AM5: =SpiriutalistMastery!O5 -> 5 | AN5: =SpiriutalistMastery!P5 -> 1 | AO5: =SpiriutalistMastery!Q5 -> 1 | AP5: =SpiriutalistMastery!R5 -> 1 | AQ5: 0 | AR5: 0 | AS5: 0 | AT5: 0
A6: =SpiriutalistMastery!B6 -> 4 | B6: =SpiriutalistMastery!C6 -> 4 | C6: =SpiriutalistMastery!D6 -> 4 | D6: =SpiriutalistMastery!E6 -> 5 | E6: 99 | F6: =SpiriutalistMastery!G6 -> 5 | G6: =SpiriutalistMastery!F6 -> 5 | H6: =SpiriutalistMastery!H6 -> 1 | I6: =SpiriutalistMastery!I6 -> 1 | J6: =SpiriutalistMastery!J6 -> 1 | K6: =SpiriutalistMastery!S6 -> 6 | L6: =SpiriutalistMastery!T6 -> 1 | M6: =SpiriutalistMastery!U6 -> 1 | N6: =SpiriutalistMastery!V6 -> 1 | O6: =SpiriutalistMastery!W6 -> 6 | P6: =SpiriutalistMastery!X6 -> 1 | Q6: =SpiriutalistMastery!Y6 -> 1 | R6: =SpiriutalistMastery!Z6 -> 1 | ... AH6: =SpiriutalistMastery!AP6 -> 1 | AI6: =SpiriutalistMastery!K6 -> 6 | AJ6: =SpiriutalistMastery!L6 -> 1 | AK6: =SpiriutalistMastery!M6 -> 1 | AL6: =SpiriutalistMastery!N6 -> 1 | AM6: =SpiriutalistMastery!O6 -> 6 | AN6: =SpiriutalistMastery!P6 -> 1 | AO6: =SpiriutalistMastery!Q6 -> 1 | AP6: =SpiriutalistMastery!R6 -> 1 | AQ6: 0 | AR6: 0 | AS6: 0 | AT6: 0
A7: =SpiriutalistMastery!B7 -> 5 | B7: =SpiriutalistMastery!C7 -> 5 | C7: =SpiriutalistMastery!D7 -> 5 | D7: =SpiriutalistMastery!E7 -> 6 | E7: 99 | F7: =SpiriutalistMastery!G7 -> 6 | G7: =SpiriutalistMastery!F7 -> 6 | H7: =SpiriutalistMastery!H7 -> 1 | I7: =SpiriutalistMastery!I7 -> 1 | J7: =SpiriutalistMastery!J7 -> 1 | K7: =SpiriutalistMastery!S7 -> 7 | L7: =SpiriutalistMastery!T7 -> 1 | M7: =SpiriutalistMastery!U7 -> 1 | N7: =SpiriutalistMastery!V7 -> 1 | O7: =SpiriutalistMastery!W7 -> 7 | P7: =SpiriutalistMastery!X7 -> 1 | Q7: =SpiriutalistMastery!Y7 -> 1 | R7: =SpiriutalistMastery!Z7 -> 1 | ... AH7: =SpiriutalistMastery!AP7 -> 1 | AI7: =SpiriutalistMastery!K7 -> 7 | AJ7: =SpiriutalistMastery!L7 -> 1 | AK7: =SpiriutalistMastery!M7 -> 1 | AL7: =SpiriutalistMastery!N7 -> 1 | AM7: =SpiriutalistMastery!O7 -> 7 | AN7: =SpiriutalistMastery!P7 -> 1 | AO7: =SpiriutalistMastery!Q7 -> 1 | AP7: =SpiriutalistMastery!R7 -> 1 | AQ7: 0 | AR7: 0 | AS7: 0 | AT7: 0
A8: =SpiriutalistMastery!B8 -> 6 | B8: =SpiriutalistMastery!C8 -> 6 | C8: =SpiriutalistMastery!D8 -> 6 | D8: =SpiriutalistMastery!E8 -> 7 | E8: 99 | F8: =SpiriutalistMastery!G8 -> 7 | G8: =SpiriutalistMastery!F8 -> 7 | H8: =SpiriutalistMastery!H8 -> 1 | I8: =SpiriutalistMastery!I8 -> 1 | J8: =SpiriutalistMastery!J8 -> 1 | K8: =SpiriutalistMastery!S8 -> 8 | L8: =SpiriutalistMastery!T8 -> 1 | M8: =SpiriutalistMastery!U8 -> 1 | N8: =SpiriutalistMastery!V8 -> 1 | O8: =SpiriutalistMastery!W8 -> 8 | P8: =SpiriutalistMastery!X8 -> 1 | Q8: =SpiriutalistMastery!Y8 -> 1 | R8: =SpiriutalistMastery!Z8 -> 1 | ... AH8: =SpiriutalistMastery!AP8 -> 1 | AI8: =SpiriutalistMastery!K8 -> 8 | AJ8: =SpiriutalistMastery!L8 -> 1 | AK8: =SpiriutalistMastery!M8 -> 1 | AL8: =SpiriutalistMastery!N8 -> 1 | AM8: =SpiriutalistMastery!O8 -> 8 | AN8: =SpiriutalistMastery!P8 -> 1 | AO8: =SpiriutalistMastery!Q8 -> 1 | AP8: =SpiriutalistMastery!R8 -> 1 | AQ8: 0 | AR8: 0 | AS8: 0 | AT8: 0
A9: =SpiriutalistMastery!B9 -> 7 | B9: =SpiriutalistMastery!C9 -> 7 | C9: =SpiriutalistMastery!D9 -> 7 | D9: =SpiriutalistMastery!E9 -> 8 | E9: 99 | F9: =SpiriutalistMastery!G9 -> 8 | G9: =SpiriutalistMastery!F9 -> 8 | H9: =SpiriutalistMastery!H9 -> 1 | I9: =SpiriutalistMastery!I9 -> 1 | J9: =SpiriutalistMastery!J9 -> 1 | K9: =SpiriutalistMastery!S9 -> 8 | L9: =SpiriutalistMastery!T9 -> 1 | M9: =SpiriutalistMastery!U9 -> 1 | N9: =SpiriutalistMastery!V9 -> 1 | O9: =SpiriutalistMastery!W9 -> 8 | P9: =SpiriutalistMastery!X9 -> 1 | Q9: =SpiriutalistMastery!Y9 -> 1 | R9: =SpiriutalistMastery!Z9 -> 1 | ... AH9: =SpiriutalistMastery!AP9 -> 1 | AI9: =SpiriutalistMastery!K9 -> 8 | AJ9: =SpiriutalistMastery!L9 -> 1 | AK9: =SpiriutalistMastery!M9 -> 1 | AL9: =SpiriutalistMastery!N9 -> 1 | AM9: =SpiriutalistMastery!O9 -> 8 | AN9: =SpiriutalistMastery!P9 -> 1 | AO9: =SpiriutalistMastery!Q9 -> 1 | AP9: =SpiriutalistMastery!R9 -> 1 | AQ9: 0 | AR9: 0 | AS9: 0 | AT9: 0
A10: =SpiriutalistMastery!B10 -> 8 | B10: =SpiriutalistMastery!C10 -> 7 | C10: =SpiriutalistMastery!D10 -> 7 | D10: =SpiriutalistMastery!E10 -> 9 | E10: 99 | F10: =SpiriutalistMastery!G10 -> 9 | G10: =SpiriutalistMastery!F10 -> 9 | H10: =SpiriutalistMastery!H10 -> 1 | I10: =SpiriutalistMastery!I10 -> 1 | J10: =SpiriutalistMastery!J10 -> 1 | K10: =SpiriutalistMastery!S10 -> 9 | L10: =SpiriutalistMastery!T10 -> 1 | M10: =SpiriutalistMastery!U10 -> 1 | N10: =SpiriutalistMastery!V10 -> 1 | O10: =SpiriutalistMastery!W10 -> 9 | P10: =SpiriutalistMastery!X10 -> 1 | Q10: =SpiriutalistMastery!Y10 -> 1 | R10: =SpiriutalistMastery!Z10 -> 1 | ... AH10: =SpiriutalistMastery!AP10 -> 1 | AI10: =SpiriutalistMastery!K10 -> 9 | AJ10: =SpiriutalistMastery!L10 -> 1 | AK10: =SpiriutalistMastery!M10 -> 1 | AL10: =SpiriutalistMastery!N10 -> 1 | AM10: =SpiriutalistMastery!O10 -> 9 | AN10: =SpiriutalistMastery!P10 -> 1 | AO10: =SpiriutalistMastery!Q10 -> 1 | AP10: =SpiriutalistMastery!R10 -> 1 | AQ10: 0 | AR10: 0 | AS10: 0 | AT10: 0
A11: =SpiriutalistMastery!B11 -> 9 | B11: =SpiriutalistMastery!C11 -> 8 | C11: =SpiriutalistMastery!D11 -> 8 | D11: =SpiriutalistMastery!E11 -> 9 | E11: 99 | F11: =SpiriutalistMastery!G11 -> 9 | G11: =SpiriutalistMastery!F11 -> 9 | H11: =SpiriutalistMastery!H11 -> 1 | I11: =SpiriutalistMastery!I11 -> 1 | J11: =SpiriutalistMastery!J11 -> 1 | K11: =SpiriutalistMastery!S11 -> 10 | L11: =SpiriutalistMastery!T11 -> 1 | M11: =SpiriutalistMastery!U11 -> 1 | N11: =SpiriutalistMastery!V11 -> 1 | O11: =SpiriutalistMastery!W11 -> 10 | P11: =SpiriutalistMastery!X11 -> 1 | Q11: =SpiriutalistMastery!Y11 -> 1 | R11: =SpiriutalistMastery!Z11 -> 1 | ... AH11: =SpiriutalistMastery!AP11 -> 1 | AI11: =SpiriutalistMastery!K11 -> 10 | AJ11: =SpiriutalistMastery!L11 -> 1 | AK11: =SpiriutalistMastery!M11 -> 1 | AL11: =SpiriutalistMastery!N11 -> 1 | AM11: =SpiriutalistMastery!O11 -> 10 | AN11: =SpiriutalistMastery!P11 -> 1 | AO11: =SpiriutalistMastery!Q11 -> 1 | AP11: =SpiriutalistMastery!R11 -> 1 | AQ11: 0 | AR11: 0 | AS11: 0 | AT11: 0
